Workbook

Sheet GENEL TAKSİT
B1: Mayıs | C1: Haziran | D1: Temmuz | E1: Ağustos | F1: Eylül | G1: Ekim | H1: Kasım | I1: Aralık
A2: Terapi | B2: 8000 | C2: 8000 | D2: 8000 | E2: 8000 | F2: 8000 | G2: 8000 | H2: 8000 | I2: 8000
A3: Yatırım 101 | B3: 650 | C3: 650 | D3: 650 | E3: 650 | F3: 650 | G3: 650 | H3: 650 | I3: 650
A4: ChatGpt | B4: 500 | C4: 500 | D4: 500 | E4: 500 | F4: 500 | G4: 500 | H4: 500 | I4: 500
A5: Claude | B5: 819 | C5: 819 | D5: 819 | E5: 819 | F5: 819 | G5: 819 | H5: 819 | I5: 819
A6: KYK | B6: 500 | C6: 500 | D6: 500 | E6: 500 | F6: 500 | G6: 500 | H6: 500 | I6: 500
A7: Kredi 1 | B7: 3625.88
A8: Nakit Avans | B8: 8530.64
A9: Beyaz esya | B9: 6408 | C9: 6408 | D9: 6408
A10: Yatak | B10: =35750/6 -> 5958.3333 | C10: =35750/6 -> 5958.3333 | D10: =35750/6 -> 5958.3333 | E10: =35750/6 -> 5958.3333
A11: Koltuk + Gardirop | B11: 4200.81 | C11: 4200.81 | D11: 4200.81 | E11: 4200.81 | F11: 4200.81 | G11: 4200.81
A12: Cayci | B12: 831.67
A13: Catal kasik | B13: 339.73
A14: Jilet | B14: 410
A15: Taksit Toplam | B15: =SUM(B2:B14) -> 40774.063 | C15: =SUM(C2:C14) -> 27036.143 | D15: =SUM(D2:D14) -> 27036.143 | E15: =SUM(E2:E14) -> 20628.143 | F15: =SUM(F2:F14) -> 14669.81 | G15: =SUM(G2:G14) -> 14669.81 | H15: =SUM(H2:H14) -> 10469 | I15: =SUM(I2:I14) -> 10469

Sheet Bütçe
B1: Bu ay | D1: Gelecek ay
A2: Kira | B2: 53000 | C2: Paid | D2: 53000
A3: Ziraat | B3: 28777.26 | C3: Paid | D3: =41029-4000-13333-5000-3333-4382 -> 10981
A4: Kredi 1 | B4: 3625.89 | C4: Paid | D4: 0
A5: Akbank | B5: 30988.39 | C5: Paid | D5: 35500
A6: Garanti | B6: 41352 | D6: 26800
A7: Terapi | B7: 8000 | C7: Paid | D7: 8000
A8: Bu Ay Toplam Borç | B8: =SUM(B2:B7) -> 165743.54 | D8: =SUM(D2:D7) -> 134281
A9: Kalan Borç | B9: =SUMIF(C2:C7,"<>Paid",B2:B7) -> 41352
A10: Ödenen Borç | B10: =sumif(C2:C7,"Paid",B2:B7) -> 124391.54

Sheet Sheet32
E3: Kira | F3: Harcama | I3: Kira | J3: Harcama
C4: 100000 | E4: 20000 | F4: 60000 | H4: =64500 -> 64500 | I4: 5000 | J4: 21000
B5: 1 | C5: =100000-20000 -> 80000 | D5: =C4-E4 -> 80000 | H5: =H4-I4-17500 -> 42000
B6: 2 | C6: =C5*0.0013+C5 -> 80104 | D6: =D5*0.0013+D5 -> 80104 | H6: =H5*0.0013+H5 -> 42054.6
B7: 3 | C7: =C6*0.0013+C6 -> 80208.135 | D7: =D6*0.0013+D6 -> 80208.135 | H7: =H6*0.0013+H6 -> 42109.271
B8: 4 | C8: =C7*0.0013+C7 -> 80312.406 | D8: =D7*0.0013+D7 -> 80312.406 | H8: =H7*0.0013+H7 -> 42164.013
B9: 5 | C9: =C8*0.0013+C8 -> 80416.812 | D9: =D8*0.0013+D8 -> 80416.812 | H9: =H8*0.0013+H8 -> 42218.826
B10: 6 | C10: =C9*0.0013+C9 -> 80521.354 | D10: =D9*0.0013+D9 -> 80521.354 | H10: =H9*0.0013+H9 -> 42273.711
B11: 7 | C11: =C10*0.0013+C10 -> 80626.032 | D11: =D10*0.0013+D10 -> 80626.032 | H11: =H10*0.0013+H10 -> 42328.667
B12: 8 | C12: =C11*0.0013+C11 -> 80730.845 | D12: =D11*0.0013+D11 -> 80730.845 | H12: =H11*0.0013+H11 -> 42383.694
B13: 9 | C13: =C12*0.0013+C12 -> 80835.795 | D13: =D12*0.0013+D12 -> 80835.795 | H13: =H12*0.0013+H12 -> 42438.793
B14: 10 | C14: =C13*0.0013+C13-F4 -> 20940.882 | D14: =D13*0.0013+D13-20000 -> 60940.882 | H14: =H13*0.0013+H13-7000 -> 35493.963
B15: 11 | C15: =C14*0.0013+C14 -> 20968.105 | D15: =D14*0.0013+D14 -> 61020.105 | H15: =H14*0.0013+H14 -> 35540.105
B16: 12 | C16: =C15*0.0013+C15 -> 20995.364 | D16: =D15*0.0013+D15 -> 61099.431 | H16: =H15*0.0013+H15 -> 35586.307
B17: 13 | C17: =C16*0.0013+C16 -> 21022.658 | D17: =D16*0.0013+D16 -> 61178.861 | H17: =H16*0.0013+H16 -> 35632.57
B18: 14 | C18: =C17*0.0013+C17 -> 21049.987 | D18: =D17*0.0013+D17 -> 61258.393 | H18: =H17*0.0013+H17 -> 35678.892
B19: 15 | C19: =C18*0.0013+C18 -> 21077.352 | D19: =D18*0.0013+D18 -> 61338.029 | H19: =H18*0.0013+H18 -> 35725.274
B20: 16 | C20: =C19*0.0013+C19 -> 21104.753 | D20: =D19*0.0013+D19 -> 61417.768 | H20: =H19*0.0013+H19 -> 35771.717
B21: 17 | C21: =C20*0.0013+C20 -> 21132.189 | D21: =D20*0.0013+D20 -> 61497.611 | H21: =H20*0.0013+H20 -> 35818.221
B22: 18 | C22: =C21*0.0013+C21 -> 21159.661 | D22: =D21*0.0013+D21 -> 61577.558 | H22: =H21*0.0013+H21 -> 35864.784
B23: 19 | C23: =C22*0.0013+C22 -> 21187.168 | D23: =D22*0.0013+D22 -> 61657.609 | H23: =H22*0.0013+H22 -> 35911.408
B24: 20 | C24: =C23*0.0013+C23 -> 21214.712 | D24: =D23*0.0013+D23-20000 -> 41737.764 | H24: =H23*0.0013+H23-7000 -> 28958.093
B25: 21 | C25: =C24*0.0013+C24 -> 21242.291 | D25: =D24*0.0013+D24 -> 41792.023 | H25: =H24*0.0013+H24 -> 28995.739
B26: 22 | C26: =C25*0.0013+C25 -> 21269.906 | D26: =D25*0.0013+D25 -> 41846.353 | H26: =H25*0.0013+H25 -> 29033.433
B27: 23 | C27: =C26*0.0013+C26 -> 21297.557 | D27: =D26*0.0013+D26 -> 41900.753 | H27: =H26*0.0013+H26 -> 29071.177
B28: 24 | C28: =C27*0.0013+C27 -> 21325.243 | D28: =D27*0.0013+D27 -> 41955.224 | H28: =H27*0.0013+H27 -> 29108.969
B29: 25 | C29: =C28*0.0013+C28 -> 21352.966 | D29: =D28*0.0013+D28 -> 42009.766 | H29: =H28*0.0013+H28 -> 29146.811
B30: 26 | C30: =C29*0.0013+C29 -> 21380.725 | D30: =D29*0.0013+D29 -> 42064.379 | H30: =H29*0.0013+H29 -> 29184.702
B31: 27 | C31: =C30*0.0013+C30 -> 21408.52 | D31: =D30*0.0013+D30 -> 42119.062 | H31: =H30*0.0013+H30 -> 29222.642
B32: 28 | C32: =C31*0.0013+C31 -> 21436.351 | D32: =D31*0.0013+D31 -> 42173.817 | H32: =H31*0.0013+H31 -> 29260.631
B33: 29 | C33: =C32*0.0013+C32 -> 21464.218 | D33: =D32*0.0013+D32 -> 42228.643 | H33: =H32*0.0013+H32 -> 29298.67
B34: 30 | C34: =C33*0.0013+C33 -> 21492.122 | D34: =D33*0.0013+D33-20000 -> 22283.54 | H34: =H33*0.0013+H33-7000 -> 22336.758
C36: =C34+F4+E4-100000 -> 1492.1218 | D36: =D34+E4+F4-100000 -> 2283.5402 | H36: =H34+I4+J4+17500 - H4 -> 1336.7584
C38: =C36/C4 -> 0.014921218 | D38: =D36/C4 -> 0.022835402 | H38: =H36/H4 -> 0.020724936

Sheet AĞUSTOS-2025
A1: Home | B1: 15250
A2: Market | B2: 5807.99
A3: Food | B3: 4758.8
A4: Taksit | B4: 16829.96
A5: Transportation | B5: 3910
A6: Shopping | B6: 3143.99
A7: Health | B7: 0
A8: Bills | B8: 1847.67
A9: Entertainment | B9: 0
A10: Personal Care | B10: 0
A11: Gifts | B11: 620
A12: Subscription | B12: 753.87
A13: Total | B13: =SUM(B1:B12) -> 52922.28

Sheet EYLÜL-2025
A1: Home | B1: 15250
A2: Market | B2: 9480.85
A3: Food | B3: 1370
A4: Taksit | B4: 15701.01
A5: Transportation | B5: 0
A6: Shopping | B6: 5154.96
A7: Health | B7: 10192
A8: Bills | B8: 1526.5
A9: Entertainment | B9: 0
A10: Personal Care | B10: 0
A11: Gifts | B11: 0
A12: Subscription | B12: 443.97
A13: Total | B13: =SUM(B1:B12) -> 59119.29

Sheet EKİM-2025
A1: Home | B1: 15250
A2: Market | B2: 6499.81
A3: Food | B3: 3834
A4: Taksit | B4: =14748.05+3625.88+8545.13 -> 26919.06
A5: Transportation | B5: 2540
A6: Bills | B6: 2194.14
A7: Subscription | B7: 458.88
A8: Shopping | B8: 165
A9: Health | B9: 0
A10: Entertainment | B10: 0
A11: Personal Care | B11: 610
A12: Gifts | B12: 0
A13: Total | B13: =SUM(B1:B12) -> 58470.89

Sheet KASIM-2025
A1: Home | B1: 15250
A2: Market | B2: 5306.38
A3: Food | B3: 3615.69
A4: Taksit | B4: 22926.96
A5: Transportation | B5: 1440
A6: Bills | B6: 2443.03
A7: Subscription | B7: 958.96
A8: Shopping | B8: 129
A9: Health | B9: 11330.9
A10: Entertainment | B10: 0
A11: Personal Care | B11: 734
A12: Gifts | B12: 778
A13: Total | B13: =SUM(B1:B12) -> 64912.92

Sheet Toplam Harcama
A1: 2024 | B1: Aylık Toplam | C1: 2025 | D1: Aylık Toplam
A2: OCAK | C2: OCAK | D2: ='OCAK-2025'!O13 -> 57056.01
A3: ŞUBAT | C3: ŞUBAT | D3: ='ŞUBAT-2025'!O13 -> 40489.31
A4: MART | C4: MART | D4: ='MART-2025'!O13 -> 64957.84
A5: NİSAN | B5: ='NİSAN-2024'!T2 | C5: NİSAN | D5: ='NİSAN-2025'!O13 -> 48412.9
A6: MAYIS | B6: ='MAYIS-2024'!T2 -> 18650.34 | C6: MAYIS | D6: ='MAYIS-2025'!O13 -> 36997.86
A7: HAZİRAN | B7: ='HAZİRAN-2024'!T2 -> 18861.93 | C7: HAZİRAN | D7: ='HAZİRAN-2025'!O13 -> 89732.36
A8: TEMMUZ | B8: ='TEMMUZ-2024'!O12 -> 24456.76 | C8: TEMMUZ | D8: ='TEMMUZ-2025'!B12 -> 104953.92
A9: AĞUSTOS | B9: ='AĞUSTOS-2024'!O12 -> 20363.52 | C9: AĞUSTOS | D9: ='AĞUSTOS-2025'!B13 -> 52922.28
A10: EYLÜL | B10: ='EYLÜL-2024'!O13 -> 21682.12 | C10: EYLÜL | D10: ='EYLÜL-2025'!B13 -> 59119.29
A11: EKİM | B11: ='EKİM-2024'!O13 -> 17501.12 | C11: EKİM | D11: ='EKİM-2025'!B13 -> 58470.89
A12: KASIM | B12: ='KASIM-2024'!O13 -> 20508.46 | C12: KASIM | D12: ='KASIM-2024'!Q13
A13: ARALIK | B13: ='ARALIK-2024'!O13 -> 57005.57 | C13: ARALIK | D13: ='ARALIK-2024'!Q13

Sheet ARALIK-2024
A1: Column 1 | B1: Date | C1: Market | D1: Food | E1: Transport | F1: Rent | G1: Bills | H1: Taksit | I1: Abonelik | J1: Fun | K1: Edu | L1: Other | M1: Daily Total
A2: 1 | B2: 45627 | C2: 235.39 | D2: =690 -> 690 | E2: 0 | F2: 0 | G2: 0 | H2: =17500 -> 17500 | I2: 0 | J2: 0 | K2: 0 | L2: 0 | M2: =SUMIF(C2:L2,"<>") -> 18425.39 | N2: Daily Avg. Food | O2: =+SUM(C2:C32,D2:D32)/ COUNTIFS(C2:C32, "<>", D2:D32, "<>") -> 311.64258
A3: 2 | B3: 45628 | C3: =129.75 -> 129.75 | D3: =280 -> 280 | E3: 0 | F3: 0 | G3: 0 | H3: 0 | I3: =26.24 -> 26.24 | J3: 0 | K3: 0 | L3: 0 | M3: =SUMIF(C3:K3,"<>") -> 435.99 | N3: Daily Avg | O3: =+O13 / COUNTIF(C2:C32, "<>") -> 1838.8894
A4: 3 | B4: 45629 | C4: =62.5 -> 62.5 | D4: 0 | E4: 0 | F4: 0 | G4: 0 | H4: 0 | I4: 0 | J4: 0 | K4: 0 | L4: 0 | M4: =SUMIF(C4:L4,"<>") -> 62.5 | N4: Market Total | O4: =+SUM(C2:C32) -> 7364.92
A5: 4 | B5: 45630 | C5: =52.75+100.75 -> 153.5 | D5: 0 | E5: 0 | F5: 0 | G5: 0 | H5: 0 | I5: 0 | J5: 0 | K5: 0 | L5: =404 -> 404 | M5: =SUMIF(C5:L5,"<>") -> 557.5 | N5: Food Total | O5: =+SUM(D2:D32) -> 2296
A6: 5 | B6: 45631 | C6: 0 | D6: 0 | E6: 0 | F6: 0 | G6: 0 | H6: 0 | I6: =39 -> 39 | J6: 0 | K6: 0 | L6: =7992 -> 7992 | M6: =SUMIF(C6:L6,"<>") -> 8031 | N6: Fun Total | O6: =SUM(J2:J32) -> 0
A7: 6 | B7: 45632 | C7: 0 | D7: =185 -> 185 | E7: 0 | F7: 0 | G7: 0 | H7: 0 | I7: 0 | J7: 0 | K7: 0 | L7: 0 | M7: =SUMIF(C7:K7,"<>") -> 185 | N7: Edu Total | O7: =SUM(K2:K32) -> 1980
A8: 7 | B8: 45633 | C8: 0 | D8: 0 | E8: =300 -> 300 | F8: 0 | G8: 0 | H8: 0 | I8: 0 | J8: 0 | K8: 0 | L8: 0 | M8: =SUMIF(C8:K8,"<>") -> 300 | N8: Trans. Total | O8: =+SUM(E2:E32) -> 550
A9: 8 | B9: 45634 | C9: =150 -> 150 | D9: 0 | E9: 0 | F9: 0 | G9: 0 | H9: 0 | I9: 0 | J9: 0 | K9: 0 | L9: 0 | M9: =SUMIF(C9:L9,"<>") -> 150 | N9: Taksit Total | O9: =Sum(H2:H32) -> 23016.39
A10: 9 | B10: 45635 | C10: =152.19 -> 152.19 | D10: 0 | E10: 0 | F10: 0 | G10: =614.9 -> 614.9 | H10: =470 -> 470 | I10: 0 | J10: 0 | K10: 0 | L10: 0 | M10: =SUMIF(C10:L10,"<>") -> 1237.09 | N10: Abonelik Top. | O10: =SUM(I2:I32) -> 65.24
A11: 10 | B11: 45636 | C11: 0 | D11: 0 | E11: 0 | F11: 0 | G11: 0 | H11: 0 | I11: 0 | J11: 0 | K11: 0 | L11: 0 | M11: =SUMIF(C11:L11,"<>") -> 0 | N11: Other Total | O11: =+SUM(L2:L32) -> 12909.62
A12: 11 | B12: 45637 | C12: =131.09+183.81 -> 314.9 | D12: 0 | E12: 0 | F12: 0 | G12: 0 | H12: =3625.88 -> 3625.88 | I12: 0 | J12: 0 | K12: 0 | L12: 0 | M12: =SUMIF(C12:L12,"<>") -> 3940.78 | N12: Bills | O12: =sum(G2:G32) -> 1823.4
A13: 12 | B13: 45638 | C13: =250 -> 250 | D13: 0 | E13: 0 | F13: 0 | G13: 0 | H13: 0 | I13: 0 | J13: 0 | K13: =1980 -> 1980 | L13: 0 | M13: =SUMIF(C13:L13,"<>") -> 2230 | N13: Total | O13: =+SUM(C2:L32) -> 57005.57
A14: 13 | B14: 45639 | C14: =299.45 -> 299.45 | D14: 0 | E14: 0 | F14: 0 | G14: 0 | H14: 0 | I14: 0 | J14: 0 | K14: 0 | L14: 0 | M14: =SUMIF(C14:L14,"<>") -> 299.45
A15: 14 | B15: 45640 | C15: =643.5 -> 643.5 | D15: =730 -> 730 | E15: 0 | F15: 0 | G15: 0 | H15: 0 | I15: 0 | J15: 0 | K15: 0 | L15: 0 | M15: =SUMIF(C15:L15,"<>") -> 1373.5
A16: 15 | B16: 45641 | C16: =196.75 -> 196.75 | D16: 0 | E16: 0 | F16: 0 | G16: 0 | H16: 0 | I16: 0 | J16: 0 | K16: 0 | L16: 0 | M16: =SUMIF(C16:L16,"<>") -> 196.75
A17: 16 | B17: 45642 | C17: =265.99 -> 265.99 | D17: 0 | E17: 0 | F17: 0 | G17: 0 | H17: 0 | I17: 0 | J17: 0 | K17: 0 | L17: 0 | M17: =SUMIF(C17:L17,"<>") -> 265.99
A18: 17 | B18: 45643 | C18: =158.7+215.76 -> 374.46 | D18: 0 | E18: 0 | F18: 0 | G18: 0 | H18: 0 | I18: 0 | J18: 0 | K18: 0 | L18: 0 | M18: =SUMIF(C18:L18,"<>") -> 374.46
A19: 18 | B19: 45644 | C19: =75.9 -> 75.9 | D19: 0 | E19: 0 | F19: 0 | G19: 0 | H19: 0 | I19: 0 | J19: 0 | K19: 0 | L19: =250 -> 250 | M19: =SUMIF(C19:L19,"<>") -> 325.9
A20: 19 | B20: 45645 | C20: =189.8+184 -> 373.8 | D20: 0 | E20: 0 | F20: 0 | G20: 0 | H20: 0 | I20: 0 | J20: 0 | K20: 0 | L20: 0 | M20: =SUMIF(C20:L20,"<>") -> 373.8
A21: 20 | B21: 45646 | C21: =51 -> 51 | D21: 0 | E21: 0 | F21: 0 | G21: 0 | H21: 0 | I21: 0 | J21: 0 | K21: 0 | L21: 0 | M21: =SUMIF(D21:L21,"<>") -> 0
A22: 21 | B22: 45647 | C22: =142.46 -> 142.46 | D22: =90 -> 90 | E22: 0 | F22: 0 | G22: 0 | H22: 0 | I22: 0 | J22: 0 | K22: 0 | L22: 0 | M22: =SUMIF(C22:L22,"<>") -> 232.46
A23: 22 | B23: 45648 | C23: =1087.41 -> 1087.41 | D23: 0 | E23: =250 -> 250 | F23: 0 | G23: 0 | H23: =1382.5 -> 1382.5 | I23: 0 | J23: 0 | K23: 0 | L23: 0 | M23: =SUMIF(C23:L23,"<>") -> 2719.91
A24: 23 | B24: 45649 | C24: 0 | D24: 0 | E24: 0 | F24: 0 | G24: 0 | H24: =38.01 -> 38.01 | I24: 0 | J24: 0 | K24: 0 | L24: =1799*2 -> 3598 | M24: =SUMIF(C24:L24,"<>") -> 3636.01
A25: 24 | B25: 45650 | C25: =362.51+45+250.62 -> 658.13 | D25: 0 | E25: 0 | F25: 0 | G25: 0 | H25: 0 | I25: 0 | J25: 0 | K25: 0 | L25: =200.32+465.3 -> 665.62 | M25: =SUMIF(C25:L25,"<>") -> 1323.75
A26: 25 | B26: 45651 | C26: 0 | D26: 0 | E26: 0 | F26: 0 | G26: 0 | H26: 0 | I26: 0 | J26: 0 | K26: 0 | L26: 0 | M26: =SUMIF(C26:L26,"<>") -> 0
A27: 26 | B27: 45652 | C27: =265.44 -> 265.44 | D27: 0 | E27: 0 | F27: 0 | G27: 0 | H27: 0 | I27: 0 | J27: 0 | K27: 0 | L27: 0 | M27: =SUMIF(C27:L27,"<>") -> 265.44
A28: 27 | B28: 45653 | C28: =73.5 -> 73.5 | D28: 0 | E28: 0 | F28: 0 | G28: 0 | H28: 0 | I28: 0 | J28: 0 | K28: 0 | L28: 0 | M28: =SUMIF(C28:L28,"<>") -> 73.5
A29: 28 | B29: 45654 | C29: =150+40.46 -> 190.46 | D29: =100 -> 100 | E29: 0 | F29: 0 | G29: 0 | H29: 0 | I29: 0 | J29: 0 | K29: 0 | L29: 0 | M29: =SUMIF(C29:L29,"<>") -> 290.46
A30: 29 | B30: 45655 | C30: =812.23 -> 812.23 | D30: 0 | E30: 0 | F30: 0 | G30: 0 | H30: 0 | I30: 0 | J30: 0 | K30: 0 | L30: 0 | M30: =SUMIF(C30:L30,"<>") -> 812.23
A31: 30 | B31: 45656 | C31: =360 -> 360 | D31: =221 -> 221 | E31: 0 | F31: 0 | G31: 0 | H31: 0 | I31: 0 | J31: 0 | K31: 0 | L31: 0 | M31: =SUMIF(C31:L31,"<>") -> 581
A32: 31 | B32: 45657 | C32: =46.21 -> 46.21 | D32: 0 | E32: 0 | F32: =5000+2000 -> 7000 | G32: =1208.5 -> 1208.5 | H32: 0 | I32: 0 | J32: 0 | K32: 0 | L32: 0 | M32: =SUMIF(C32:L32,"<>") -> 8254.71

Sheet OCAK-2025
B1: Date | C1: Market | D1: Food | E1: Transport | F1: Rent | G1: Bills | H1: Taksit | I1: Abonelik | J1: Fun | K1: Edu | L1: Other | M1: Daily Total
A2: 1 | B2: 45658 | C2: 0 | D2: 0 | E2: 0 | F2: 0 | G2: 0 | H2: =17400 -> 17400 | I2: 0 | J2: 0 | K2: 0 | L2: 0 | M2: =SUMIF(C2:L2,"<>") -> 17400 | N2: Daily Avg. Food | O2: =+SUM(C2:C32,D2:D32)/ COUNTIFS(C2:C32, "<>", D2:D32, "<>") -> 239.43839
A3: 2 | B3: 45659 | C3: 0 | D3: 0 | E3: 0 | F3: 0 | G3: 0 | H3: =470 -> 470 | I3: =25.9 -> 25.9 | J3: 0 | K3: 0 | L3: 0 | M3: =SUMIF(C3:K3,"<>") -> 495.9 | N3: Daily Avg | O3: =+O13 / COUNTIF(C2:C32, "<>") -> 1840.5165
A4: 3 | B4: 45660 | C4: 0 | D4: 0 | E4: 0 | F4: 0 | G4: 0 | H4: 0 | I4: =19.74 -> 19.74 | J4: 0 | K4: 0 | L4: 0 | M4: =SUMIF(C4:L4,"<>") -> 19.74 | N4: Market Total | O4: =+SUM(C2:C32) -> 4644.85
A5: 4 | B5: 45661 | C5: 0 | D5: 0 | E5: 0 | F5: 0 | G5: 0 | H5: 0 | I5: 0 | J5: 0 | K5: 0 | L5: 0 | M5: =SUMIF(C5:L5,"<>") -> 0 | N5: Food Total | O5: =+SUM(D2:D32) -> 2777.74
A6: 5 | B6: 45662 | C6: =277.41 -> 277.41 | D6: =285 -> 285 | E6: 0 | F6: 0 | G6: 0 | H6: 0 | I6: =39 -> 39 | J6: 0 | K6: 0 | L6: 0 | M6: =SUMIF(C6:L6,"<>") -> 601.41 | N6: Fun Total | O6: =SUM(J2:J32) -> 0
A7: 6 | B7: 45663 | C7: 0 | D7: 0 | E7: =300 -> 300 | F7: 0 | G7: 0 | H7: 0 | I7: 0 | J7: 0 | K7: 0 | L7: 0 | M7: =SUMIF(C7:K7,"<>") -> 300 | N7: Edu Total | O7: =SUM(K2:K32) -> 0
A8: 7 | B8: 45664 | C8: =44.58 -> 44.58 | D8: 0 | E8: 0 | F8: 0 | G8: =615 -> 615 | H8: 0 | I8: 0 | J8: 0 | K8: 0 | L8: 0 | M8: =SUMIF(C8:K8,"<>") -> 659.58 | N8: Trans. Total | O8: =+SUM(E2:E32) -> 6025.03
A9: 8 | B9: 45665 | C9: =131.5+138.2 -> 269.7 | D9: 0 | E9: 0 | F9: 0 | G9: 0 | H9: 0 | I9: 0 | J9: 0 | K9: 0 | L9: 0 | M9: =SUMIF(C9:L9,"<>") -> 269.7 | N9: Taksit Total | O9: =Sum(H2:H32) -> 23293.7
A10: 9 | B10: 45666 | C10: 0 | D10: 0 | E10: 0 | F10: 0 | G10: 0 | H10: 0 | I10: 0 | J10: 0 | K10: 0 | L10: 0 | M10: =SUMIF(C10:L10,"<>") -> 0 | N10: Abonelik Top. | O10: =SUM(I2:I32) -> 188.54
A11: 10 | B11: 45667 | C11: 0 | D11: =200 -> 200 | E11: 0 | F11: 0 | G11: 0 | H11: 0 | I11: 0 | J11: 0 | K11: 0 | L11: 0 | M11: =SUMIF(C11:L11,"<>") -> 200 | N11: Other Total | O11: =+SUM(L2:L32) -> 9911.15
A12: 11 | B12: 45668 | C12: =59.95 -> 59.95 | D12: 0 | E12: 0 | F12: 0 | G12: 0 | H12: =3625.88 -> 3625.88 | I12: =103.9 -> 103.9 | J12: 0 | K12: 0 | L12: 0 | M12: =SUMIF(C12:L12,"<>") -> 3789.73 | N12: Bills | O12: =sum(G2:G32) -> 3215
A13: 12 | B13: 45669 | C13: 0 | D13: 0 | E13: 0 | F13: 0 | G13: 0 | H13: 0 | I13: 0 | J13: 0 | K13: 0 | L13: 0 | M13: =SUMIF(C13:L13,"<>") -> 0 | N13: Total | O13: =+SUM(C2:L32) -> 57056.01
A14: 13 | B14: 45670 | C14: 0 | D14: 0 | E14: 0 | F14: 0 | G14: 0 | H14: 0 | I14: 0 | J14: 0 | K14: 0 | L14: 0 | M14: =SUMIF(C14:L14,"<>") -> 0
A15: 14 | B15: 45671 | C15: 0 | D15: 0 | E15: 0 | F15: 0 | G15: 0 | H15: 0 | I15: 0 | J15: 0 | K15: 0 | L15: 0 | M15: =SUMIF(C15:L15,"<>") -> 0
A16: 15 | B16: 45672 | C16: 0 | D16: 0 | E16: 0 | F16: 0 | G16: 0 | H16: 0 | I16: 0 | J16: 0 | K16: 0 | L16: 0 | M16: =SUMIF(C16:L16,"<>") -> 0
A17: 16 | B17: 45673 | C17: 0 | D17: 0 | E17: 0 | F17: 0 | G17: 0 | H17: 0 | I17: 0 | J17: 0 | K17: 0 | L17: 0 | M17: =SUMIF(C17:L17,"<>") -> 0
A18: 17 | B18: 45674 | C18: 0 | D18: 0 | E18: 0 | F18: 0 | G18: 0 | H18: =177.5 -> 177.5 | I18: 0 | J18: 0 | K18: 0 | L18: 0 | M18: =SUMIF(C18:L18,"<>") -> 177.5
A19: 18 | B19: 45675 | C19: 0 | D19: =100 -> 100 | E19: 0 | F19: 0 | G19: 0 | H19: 0 | I19: 0 | J19: 0 | K19: 0 | L19: 0 | M19: =SUMIF(C19:L19,"<>") -> 100
A20: 19 | B20: 45676 | C20: =88.89 -> 88.89 | D20: 0 | E20: 0 | F20: 0 | G20: 0 | H20: 0 | I20: 0 | J20: 0 | K20: 0 | L20: 0 | M20: =SUMIF(C20:L20,"<>") -> 88.89
A21: 20 | B21: 45677 | C21: 0 | D21: 0 | E21: 0 | F21: 0 | G21: 0 | H21: 0 | I21: 0 | J21: 0 | K21: 0 | L21: 0 | M21: =SUMIF(D21:L21,"<>") -> 0
A22: 21 | B22: 45678 | C22: =253.02 -> 253.02 | D22: =839.32 -> 839.32 | E22: =1205 -> 1205 | F22: 0 | G22: 0 | H22: 0 | I22: 0 | J22: 0 | K22: 0 | L22: =9739.91 -> 9739.91 | M22: =SUMIF(C22:L22,"<>") -> 12037.25
A23: 22 | B23: 45679 | C23: =686.32+144.84+301.57 -> 1132.73 | D23: =116.24 -> 116.24 | E23: =696.71 -> 696.71 | F23: 0 | G23: 0 | H23: 0 | I23: 0 | J23: 0 | K23: 0 | L23: 0 | M23: =SUMIF(C23:L23,"<>") -> 1945.68
A24: 23 | B24: 45680 | C24: =343.63+646.83 -> 990.46 | D24: =1017.18 -> 1017.18 | E24: 0 | F24: 0 | G24: 0 | H24: 0 | I24: 0 | J24: 0 | K24: 0 | L24: 0 | M24: =SUMIF(C24:L24,"<>") -> 2007.64
A25: 24 | B25: 45681 | C25: 0 | D25: 0 | E25: =1963.32 -> 1963.32 | F25: 0 | G25: 0 | H25: =200.32 -> 200.32 | I25: 0 | J25: 0 | K25: 0 | L25: 0 | M25: =SUMIF(C25:L25,"<>") -> 2163.64
A26: 25 | B26: 45682 | C26: =886.5+190 -> 1076.5 | D26: 0 | E26: =780*2 -> 1560 | F26: 0 | G26: 0 | H26: 0 | I26: 0 | J26: 0 | K26: 0 | L26: 0 | M26: =SUMIF(C26:L26,"<>") -> 2636.5
A27: 26 | B27: 45683 | C27: =129.3+142.13 -> 271.43 | D27: 0 | E27: =300 -> 300 | F27: 0 | G27: 0 | H27: 0 | I27: 0 | J27: 0 | K27: 0 | L27: 0 | M27: =SUMIF(C27:L27,"<>") -> 571.43
A28: 27 | B28: 45684 | C28: =37.5 -> 37.5 | D28: =220 -> 220 | E28: 0 | F28: 0 | G28: 0 | H28: 0 | I28: 0 | J28: 0 | K28: 0 | L28: 0 | M28: =SUMIF(C28:L28,"<>") -> 257.5
A29: 28 | B29: 45685 | C29: 0 | D29: 0 | E29: 0 | F29: 0 | G29: 0 | H29: 0 | I29: 0 | J29: 0 | K29: 0 | L29: =171.24 -> 171.24 | M29: =SUMIF(C29:L29,"<>") -> 171.24
A30: 29 | B30: 45686 | C30: =142.68 -> 142.68 | D30: 0 | E30: 0 | F30: 0 | G30: 0 | H30: 0 | I30: 0 | J30: 0 | K30: 0 | L30: 0 | M30: =SUMIF(C30:L30,"<>") -> 142.68
A31: 30 | B31: 45687 | C31: 0 | D31: 0 | E31: 0 | F31: 0 | G31: 0 | H31: 0 | I31: 0 | J31: 0 | K31: 0 | L31: 0 | M31: =SUMIF(C31:L31,"<>") -> 0
A32: 31 | B32: 45688 | C32: 0 | D32: 0 | E32: 0 | F32: =7000 -> 7000 | G32: =2600 -> 2600 | H32: =1420 -> 1420 | I32: 0 | J32: 0 | K32: 0 | L32: 0 | M32: =SUMIF(C32:L32,"<>") -> 11020

Sheet ŞUBAT-2025
B1: Date | C1: Market | D1: Food | E1: Transport | F1: Rent | G1: Bills | H1: Taksit | I1: Abonelik | J1: Fun | K1: Edu | L1: Other | M1: Daily Total
A2: 1 | B2: 45689 | C2: =256.2 -> 256.2 | D2: 0 | E2: =250 -> 250 | F2: 0 | G2: 0 | H2: =17400 -> 17400 | I2: 0 | J2: 0 | K2: 0 | L2: =69.7 -> 69.7 | M2: =SUMIF(C2:L2,"<>") -> 17975.9 | N2: Daily Avg. Food | O2: =+SUM(C2:C29,D2:D29)/ COUNTIFS(C2:C29, "<>", D2:D29, "<>") -> 177.61536
A3: 2 | B3: 45690 | C3: =280.5+40.49+85.11 -> 406.1 | D3: 0 | E3: 0 | F3: 0 | G3: 0 | H3: 0 | I3: =25.95 -> 25.95 | J3: 0 | K3: 0 | L3: 0 | M3: =SUMIF(C3:K3,"<>") -> 432.05 | N3: Daily Avg | O3: =+O13 / COUNTIF(C2:C29, "<>") -> 1446.0468
A4: 3 | B4: 45691 | C4: 0 | D4: 0 | E4: 0 | F4: 0 | G4: 0 | H4: =470 -> 470 | I4: =19.71 -> 19.71 | J4: 0 | K4: 0 | L4: 0 | M4: =SUMIF(C4:L4,"<>") -> 489.71 | N4: Market Total | O4: =+SUM(C2:C29) -> 2964.23
A5: 4 | B5: 45692 | C5: =85 -> 85 | D5: 0 | E5: 0 | F5: 0 | G5: 0 | H5: 0 | I5: 0 | J5: 0 | K5: 0 | L5: 0 | M5: =SUMIF(C5:L5,"<>") -> 85 | N5: Food Total | O5: =+SUM(D2:D29) -> 2009
A6: 5 | B6: 45693 | C6: 0 | D6: =635 -> 635 | E6: 0 | F6: 0 | G6: 0 | H6: 0 | I6: =39 -> 39 | J6: 0 | K6: 0 | L6: 0 | M6: =SUMIF(C6:L6,"<>") -> 674 | N6: Fun Total | O6: =SUM(J2:J29) -> 300
A7: 6 | B7: 45694 | C7: =29+49.99 -> 78.99 | D7: 0 | E7: 0 | F7: 0 | G7: 0 | H7: 0 | I7: 0 | J7: 0 | K7: 0 | L7: 0 | M7: =SUMIF(C7:K7,"<>") -> 78.99 | N7: Edu Total | O7: =SUM(K2:K29) -> 0
A8: 7 | B8: 45695 | C8: =60 -> 60 | D8: =380 -> 380 | E8: 0 | F8: 0 | G8: 0 | H8: 0 | I8: 0 | J8: 0 | K8: 0 | L8: 0 | M8: =SUMIF(C8:K8,"<>") -> 440 | N8: Trans. Total | O8: =+SUM(E2:E29) -> 454.99
A9: 8 | B9: 45696 | C9: =355.29 -> 355.29 | D9: 0 | E9: 0 | F9: 0 | G9: =671.5 -> 671.5 | H9: 0 | I9: 0 | J9: 0 | K9: 0 | L9: 0 | M9: =SUMIF(C9:L9,"<>") -> 1026.79 | N9: Taksit Total | O9: =Sum(H2:H29) -> 29469.09
A10: 9 | B10: 45697 | C10: 0 | D10: 0 | E10: 0 | F10: 0 | G10: 0 | H10: 0 | I10: 0 | J10: 0 | K10: 0 | L10: 0 | M10: =SUMIF(C10:L10,"<>") -> 0 | N10: Abonelik Top. | O10: =SUM(I2:I29) -> 84.66
A11: 10 | B11: 45698 | C11: 0 | D11: 0 | E11: 0 | F11: 0 | G11: 0 | H11: 0 | I11: 0 | J11: 0 | K11: 0 | L11: =320 -> 320 | M11: =SUMIF(C11:L11,"<>") -> 320 | N11: Other Total | O11: =+SUM(L2:L29) -> 3184.7
A12: 11 | B12: 45699 | C12: 0 | D12: 0 | E12: 0 | F12: 0 | G12: 0 | H12: =3625.88 -> 3625.88 | I12: 0 | J12: =300 -> 300 | K12: 0 | L12: 0 | M12: =SUMIF(C12:L12,"<>") -> 3925.88 | N12: Bills | O12: =sum(G2:G29) -> 2022.64
A13: 12 | B13: 45700 | C13: 0 | D13: =250 -> 250 | E13: 0 | F13: 0 | G13: 0 | H13: =5666.5 -> 5666.5 | I13: 0 | J13: 0 | K13: 0 | L13: 0 | M13: =SUMIF(C13:L13,"<>") -> 5916.5 | N13: Total | O13: =+SUM(C2:L29) -> 40489.31
A14: 13 | B14: 45701 | C14: =94 -> 94 | D14: 0 | E14: 0 | F14: 0 | G14: 0 | H14: 0 | I14: 0 | J14: 0 | K14: 0 | L14: =360 -> 360 | M14: =SUMIF(C14:L14,"<>") -> 454
A15: 14 | B15: 45702 | C15: 0 | D15: 0 | E15: 0 | F15: 0 | G15: 0 | H15: 0 | I15: 0 | J15: 0 | K15: 0 | L15: 0 | M15: =SUMIF(C15:L15,"<>") -> 0
A16: 15 | B16: 45703 | C16: =125.77 -> 125.77 | D16: 0 | E16: =204.99 -> 204.99 | F16: 0 | G16: 0 | H16: 0 | I16: 0 | J16: 0 | K16: 0 | L16: 0 | M16: =SUMIF(C16:L16,"<>") -> 330.76
A17: 16 | B17: 45704 | C17: =76.9+57.75 -> 134.65 | D17: 0 | E17: 0 | F17: 0 | G17: 0 | H17: 0 | I17: 0 | J17: 0 | K17: 0 | L17: 0 | M17: =SUMIF(C17:L17,"<>") -> 134.65
A18: 17 | B18: 45705 | C18: =139.57+62.79 -> 202.36 | D18: 0 | E18: 0 | F18: 0 | G18: 0 | H18: =177.5+593.06 -> 770.56 | I18: 0 | J18: 0 | K18: 0 | L18: 0 | M18: =SUMIF(C18:L18,"<>") -> 972.92
A19: 18 | B19: 45706 | C19: 0 | D19: 0 | E19: 0 | F19: 0 | G19: =1351.14 -> 1351.14 | H19: 0 | I19: 0 | J19: 0 | K19: 0 | L19: 0 | M19: =SUMIF(C19:L19,"<>") -> 1351.14
A20: 19 | B20: 45707 | C20: =63.75 -> 63.75 | D20: 0 | E20: 0 | F20: 0 | G20: 0 | H20: =1335.83 -> 1335.83 | I20: 0 | J20: 0 | K20: 0 | L20: 0 | M20: =SUMIF(C20:L20,"<>") -> 1399.58
A21: 20 | B21: 45708 | C21: =158 -> 158 | D21: 0 | E21: 0 | F21: 0 | G21: 0 | H21: 0 | I21: 0 | J21: 0 | K21: 0 | L21: =350 -> 350 | M21: =SUMIF(D21:L21,"<>") -> 350
A22: 21 | B22: 45709 | C22: =83.9 -> 83.9 | D22: 0 | E22: 0 | F22: 0 | G22: 0 | H22: 0 | I22: 0 | J22: 0 | K22: 0 | L22: 0 | M22: =SUMIF(C22:L22,"<>") -> 83.9
A23: 22 | B23: 45710 | C23: =52.5+138.75 -> 191.25 | D23: =510 -> 510 | E23: 0 | F23: 0 | G23: 0 | H23: 0 | I23: 0 | J23: 0 | K23: 0 | L23: =140+160+35 -> 335 | M23: =SUMIF(C23:L23,"<>") -> 1036.25
A24: 23 | B24: 45711 | C24: =57+15.59+90.5 -> 163.09 | D24: 0 | E24: 0 | F24: 0 | G24: 0 | H24: 0 | I24: 0 | J24: 0 | K24: 0 | L24: =450 -> 450 | M24: =SUMIF(C24:L24,"<>") -> 613.09
A25: 24 | B25: 45712 | C25: =92 -> 92 | D25: 0 | E25: 0 | F25: 0 | G25: 0 | H25: =200.32 -> 200.32 | I25: 0 | J25: 0 | K25: 0 | L25: 0 | M25: =SUMIF(C25:L25,"<>") -> 292.32
A26: 25 | B26: 45713 | C26: 0 | D26: =234 -> 234 | E26: 0 | F26: 0 | G26: 0 | H26: 0 | I26: 0 | J26: 0 | K26: 0 | L26: =100+1200 -> 1300 | M26: =SUMIF(C26:L26,"<>") -> 1534
A27: 26 | B27: 45714 | C27: =76.5+74.93 -> 151.43 | D27: 0 | E27: 0 | F27: 0 | G27: 0 | H27: 0 | I27: 0 | J27: 0 | K27: 0 | L27: 0 | M27: =SUMIF(C27:L27,"<>") -> 151.43
A28: 27 | B28: 45715 | C28: 0 | D28: 0 | E28: 0 | F28: 0 | G28: 0 | H28: 0 | I28: 0 | J28: 0 | K28: 0 | L28: 0 | M28: =SUMIF(C28:L28,"<>") -> 0
A29: 28 | B29: 45716 | C29: =262.45 -> 262.45 | D29: 0 | E29: 0 | F29: 0 | G29: 0 | H29: 0 | I29: 0 | J29: 0 | K29: 0 | L29: 0 | M29: =SUMIF(C29:L29,"<>") -> 262.45

Sheet MART-2025
B1: Date | C1: Market | D1: Food | E1: Transport | F1: Rent | G1: Bills | H1: Taksit | I1: Abonelik | J1: Fun | K1: Edu | L1: Other | M1: Daily Total
A2: 1 | B2: 45717 | C2: 0 | D2: 0 | E2: 0 | F2: =250 -> 250 | G2: 0 | H2: 0 | I2: 0 | J2: 0 | K2: 0 | L2: 0 | M2: =SUMIF(C2:L2,"<>") -> 250 | N2: Daily Avg. Food | O2: =+SUM(C2:C32,D2:D29)/ COUNTIFS(C2:C29, "<>", D2:D29, "<>") -> 290.69786
A3: 2 | B3: 45718 | C3: =23+35+45.48+82+239.72 -> 425.2 | D3: 0 | E3: 0 | F3: 0 | G3: 0 | H3: 0 | I3: =26.03 -> 26.03 | J3: 0 | K3: 0 | L3: 0 | M3: =SUMIF(C3:K3,"<>") -> 451.23 | N3: Daily Avg | O3: =+O13 / COUNTIF(C2:C32, "<>") -> 2095.4142
A4: 3 | B4: 45719 | C4: =173.65+281.7 -> 455.35 | D4: 0 | E4: 0 | F4: 0 | G4: 0 | H4: =470 -> 470 | I4: =19.57 -> 19.57 | J4: 0 | K4: 0 | L4: =170 -> 170 | M4: =SUMIF(C4:L4,"<>") -> 1114.92 | N4: Market Total | O4: =+SUM(C2:C32) -> 7042.54
A5: 4 | B5: 45720 | C5: 0 | D5: 0 | E5: =780 -> 780 | F5: 0 | G5: 0 | H5: 0 | I5: 0 | J5: 0 | K5: 0 | L5: =265 -> 265 | M5: =SUMIF(C5:L5,"<>") -> 1045 | N5: Food Total | O5: =+SUM(D2:D32) -> 1382
A6: 5 | B6: 45721 | C6: =617.25 -> 617.25 | D6: 0 | E6: 0 | F6: 0 | G6: 0 | H6: 0 | I6: =39 -> 39 | J6: 0 | K6: 0 | L6: 0 | M6: =SUMIF(C6:L6,"<>") -> 656.25 | N6: Fun Total | O6: =SUM(J2:J32) -> 0
A7: 6 | B7: 45722 | C7: =50+55 -> 105 | D7: 0 | E7: 0 | F7: 0 | G7: 0 | H7: 0 | I7: 0 | J7: 0 | K7: 0 | L7: 0 | M7: =SUMIF(C7:K7,"<>") -> 105 | N7: Edu Total | O7: =SUM(K2:K32) -> 0
A8: 7 | B8: 45723 | C8: 0 | D8: =234 -> 234 | E8: 0 | F8: 0 | G8: 0 | H8: 0 | I8: 0 | J8: 0 | K8: 0 | L8: 0 | M8: =SUMIF(C8:K8,"<>") -> 234 | N8: Trans. Total | O8: =+SUM(E2:E32) -> 3623.57
A9: 8 | B9: 45724 | C9: =50+176.25+279.11 -> 505.36 | D9: 0 | E9: 0 | F9: 0 | G9: 0 | H9: 0 | I9: 0 | J9: 0 | K9: 0 | L9: 0 | M9: =SUMIF(C9:L9,"<>") -> 505.36 | N9: Taksit Total | O9: =Sum(H2:H32) -> 12484.7
A10: 9 | B10: 45725 | C10: =165 -> 165 | D10: 0 | E10: 0 | F10: 0 | G10: =674.1+80.7+303.51+210 -> 1268.31 | H10: 0 | I10: 0 | J10: 0 | K10: 0 | L10: 0 | M10: =SUMIF(C10:L10,"<>") -> 1433.31 | N10: Abonelik Top. | O10: =SUM(I2:I32) -> 84.6
A11: 10 | B11: 45726 | C11: 0 | D11: 0 | E11: 0 | F11: 0 | G11: 0 | H11: 0 | I11: 0 | J11: 0 | K11: 0 | L11: 0 | M11: =SUMIF(C11:L11,"<>") -> 0 | N11: Other Total | O11: =+SUM(L2:L32) -> 23778.55
A12: 11 | B12: 45727 | C12: =25+54.9 -> 79.9 | D12: =150 -> 150 | E12: 0 | F12: 0 | G12: 0 | H12: =3625.88 -> 3625.88 | I12: 0 | J12: 0 | K12: 0 | L12: =690 -> 690 | M12: =SUMIF(C12:L12,"<>") -> 4545.78 | N12: Bills | O12: =sum(G2:G32) -> 1311.88
A13: 12 | B13: 45728 | C13: 0 | D13: 0 | E13: 0 | F13: 0 | G13: =43.57 -> 43.57 | H13: =5666.5 -> 5666.5 | I13: 0 | J13: 0 | K13: 0 | L13: 0 | M13: =SUMIF(C13:L13,"<>") -> 5710.07 | N13: Total | O13: =+SUM(C2:L32) -> 64957.84
A14: 13 | B14: 45729 | C14: =40 -> 40 | D14: 0 | E14: 0 | F14: 0 | G14: 0 | H14: 0 | I14: 0 | J14: 0 | K14: 0 | L14: 0 | M14: =SUMIF(C14:L14,"<>") -> 40
A15: 14 | B15: 45730 | C15: 0 | D15: 0 | E15: 0 | F15: 0 | G15: 0 | H15: 0 | I15: 0 | J15: 0 | K15: 0 | L15: 0 | M15: =SUMIF(C15:L15,"<>") -> 0
A16: 15 | B16: 45731 | C16: =187+105 -> 292 | D16: 0 | E16: 0 | F16: =15000 -> 15000 | G16: 0 | H16: 0 | I16: 0 | J16: 0 | K16: 0 | L16: =300 -> 300 | M16: =SUMIF(C16:L16,"<>") -> 15592
A17: 16 | B17: 45732 | C17: =62+52.5+308.4+231.5 -> 654.4 | D17: 0 | E17: 0 | F17: 0 | G17: 0 | H17: =366 -> 366 | I17: 0 | J17: 0 | K17: 0 | L17: =115+89+279.9+758.65 -> 1242.55 | M17: =SUMIF(C17:L17,"<>") -> 2262.95
A18: 17 | B18: 45733 | C18: =201 -> 201 | D18: 0 | E18: 0 | F18: 0 | G18: 0 | H18: =177.5+537 -> 714.5 | I18: 0 | J18: 0 | K18: 0 | L18: 0 | M18: =SUMIF(C18:L18,"<>") -> 915.5
A19: 18 | B19: 45734 | C19: =467.36 -> 467.36 | D19: 0 | E19: 0 | F19: 0 | G19: 0 | H19: 0 | I19: 0 | J19: 0 | K19: 0 | L19: 0 | M19: =SUMIF(C19:L19,"<>") -> 467.36
A20: 19 | B20: 45735 | C20: =213.95+275.69 -> 489.64 | D20: 0 | E20: =700 -> 700 | F20: 0 | G20: 0 | H20: =306+1335.82 -> 1641.82 | I20: 0 | J20: 0 | K20: 0 | L20: =299+10800 -> 11099 | M20: =SUMIF(C20:L20,"<>") -> 13930.46
A21: 20 | B21: 45736 | C21: =300.09 -> 300.09 | D21: =234 -> 234 | E21: 0 | F21: 0 | G21: 0 | H21: 0 | I21: 0 | J21: 0 | K21: 0 | L21: 0 | M21: =SUMIF(D21:L21,"<>") -> 234
A22: 21 | B22: 45737 | C22: =552.45 -> 552.45 | D22: 0 | E22: 0 | F22: 0 | G22: 0 | H22: 0 | I22: 0 | J22: 0 | K22: 0 | L22: =170 -> 170 | M22: =SUMIF(C22:L22,"<>") -> 722.45
A23: 22 | B23: 45738 | C23: =150 -> 150 | D23: =234 -> 234 | E23: 0 | F23: 0 | G23: 0 | H23: 0 | I23: 0 | J23: 0 | K23: 0 | L23: =50 -> 50 | M23: =SUMIF(C23:L23,"<>") -> 434
A24: 23 | B24: 45739 | C24: =1173.14+119.9 -> 1293.04 | D24: 0 | E24: 0 | F24: 0 | G24: 0 | H24: 0 | I24: 0 | J24: 0 | K24: 0 | L24: 0 | M24: =SUMIF(C24:L24,"<>") -> 1293.04
A25: 24 | B25: 45740 | C25: =88.5+161 -> 249.5 | D25: 0 | E25: 0 | F25: 0 | G25: 0 | H25: 0 | I25: 0 | J25: 0 | K25: 0 | L25: =9792 -> 9792 | M25: =SUMIF(C25:L25,"<>") -> 10041.5
A26: 25 | B26: 45741 | C26: 0 | D26: 0 | E26: 0 | F26: 0 | G26: 0 | H26: 0 | I26: 0 | J26: 0 | K26: 0 | L26: 0 | M26: =SUMIF(C26:L26,"<>") -> 0
A27: 26 | B27: 45742 | C27: 0 | D27: =75 -> 75 | E27: =780+635 -> 1415 | F27: 0 | G27: 0 | H27: 0 | I27: 0 | J27: 0 | K27: 0 | L27: 0 | M27: =SUMIF(C27:L27,"<>") -> 1490
A28: 27 | B28: 45743 | C28: 0 | D28: 0 | E28: 0 | F28: 0 | G28: 0 | H28: 0 | I28: 0 | J28: 0 | K28: 0 | L28: 0 | M28: =SUMIF(C28:L28,"<>") -> 0
A29: 28 | B29: 45744 | C29: 0 | D29: =170 -> 170 | E29: 0 | F29: 0 | G29: 0 | H29: 0 | I29: 0 | J29: 0 | K29: 0 | L29: 0 | M29: =SUMIF(C29:L29,"<>") -> 170
A30: 29 | B30: 45745 | C30: 0 | D30: =60 -> 60 | E30: =30.57 -> 30.57 | F30: 0 | G30: 0 | H30: 0 | I30: 0 | J30: 0 | K30: 0 | L30: 0 | M30: =SUMIF(C30:L30,"<>") -> 90.57
A31: 30 | B31: 45746 | C31: 0 | D31: 0 | E31: =698 -> 698 | F31: 0 | G31: 0 | H31: 0 | I31: 0 | J31: 0 | K31: 0 | L31: 0 | M31: =SUMIF(C31:L31,"<>") -> 698
A32: 31 | B32: 45747 | C32: 0 | D32: =225 -> 225 | E32: 0 | F32: 0 | G32: 0 | H32: 0 | I32: 0 | J32: 0 | K32: 0 | L32: 0 | M32: =SUMIF(C32:L32,"<>") -> 225

Sheet NİSAN-2025
B1: Date | C1: Market | D1: Food | E1: Transport | F1: Rent | G1: Bills | H1: Taksit | I1: Abonelik | J1: Fun | K1: Edu | L1: Other | M1: Daily Total
A2: 1 | B2: 45748 | C2: 0 | D2: 0 | E2: 0 | F2: =250 -> 250 | G2: 0 | H2: 0 | I2: 0 | J2: 0 | K2: 0 | L2: 0 | M2: =SUMIF(C2:L2,"<>") -> 250 | N2: Daily Avg. Food | O2: =+SUM(C2:C31,D2:D31)/ COUNTIFS(C2:C31, "<>", D2:D31, "<>") -> 477.47633
A3: 2 | B3: 45749 | C3: 0 | D3: 0 | E3: 0 | F3: 0 | G3: =671.5 -> 671.5 | H3: =406.32 -> 406.32 | I3: =26.45 -> 26.45 | J3: 0 | K3: 0 | L3: 0 | M3: =SUMIF(C3:K3,"<>") -> 1104.27 | N3: Daily Avg | O3: =+O13 / COUNTIF(C2:C31, "<>") -> 1613.7633
A4: 3 | B4: 45750 | C4: =397 -> 397 | D4: 0 | E4: 0 | F4: 0 | G4: =725.75 -> 725.75 | H4: =470 -> 470 | I4: =20.16 -> 20.16 | J4: 0 | K4: 0 | L4: 0 | M4: =SUMIF(C4:L4,"<>") -> 1612.91 | N4: Market Total | O4: =+SUM(C2:C31) -> 5538.44
A5: 4 | B5: 45751 | C5: 0 | D5: 0 | E5: 0 | F5: 0 | G5: 0 | H5: 0 | I5: 0 | J5: 0 | K5: 0 | L5: =185 -> 185 | M5: =SUMIF(C5:L5,"<>") -> 185 | N5: Food Total | O5: =+SUM(D2:D31) -> 8785.85
A6: 5 | B6: 45752 | C6: =100.82 -> 100.82 | D6: 0 | E6: 0 | F6: 0 | G6: 0 | H6: 0 | I6: =39 -> 39 | J6: 0 | K6: 0 | L6: 0 | M6: =SUMIF(C6:L6,"<>") -> 139.82 | N6: Fun Total | O6: =SUM(J2:J31) -> 0
A7: 6 | B7: 45753 | C7: 0 | D7: =234 -> 234 | E7: 0 | F7: 0 | G7: 0 | H7: 0 | I7: 0 | J7: 0 | K7: 0 | L7: 0 | M7: =SUMIF(C7:K7,"<>") -> 234 | N7: Edu Total | O7: =SUM(K2:K31) -> 0
A8: 7 | B8: 45754 | C8: 0 | D8: 0 | E8: 0 | F8: 0 | G8: 0 | H8: 0 | I8: 0 | J8: 0 | K8: 0 | L8: 0 | M8: =SUMIF(C8:K8,"<>") -> 0 | N8: Trans. Total | O8: =+SUM(E2:E31) -> 1560
A9: 8 | B9: 45755 | C9: =26.95 -> 26.95 | D9: 0 | E9: 0 | F9: 0 | G9: 0 | H9: 0 | I9: 0 | J9: 0 | K9: 0 | L9: =1190 -> 1190 | M9: =SUMIF(C9:L9,"<>") -> 1216.95 | N9: Taksit Total | O9: =Sum(H2:H31) -> 13913.81
A10: 9 | B10: 45756 | C10: 0 | D10: =425.85 -> 425.85 | E10: 0 | F10: 0 | G10: 0 | H10: 0 | I10: 0 | J10: 0 | K10: 0 | L10: 0 | M10: =SUMIF(C10:L10,"<>") -> 425.85 | N10: Abonelik Top. | O10: =SUM(I2:I31) -> 85.61
A11: 10 | B11: 45757 | C11: 0 | D11: =221 -> 221 | E11: 0 | F11: 0 | G11: 0 | H11: 0 | I11: 0 | J11: 0 | K11: 0 | L11: 0 | M11: =SUMIF(C11:L11,"<>") -> 221 | N11: Other Total | O11: =+SUM(L2:L31) -> 1708.06
A12: 11 | B12: 45758 | C12: 0 | D12: =620 -> 620 | E12: 0 | F12: 0 | G12: 0 | H12: =3625.88 -> 3625.88 | I12: 0 | J12: 0 | K12: 0 | L12: 0 | M12: =SUMIF(C12:L12,"<>") -> 4245.88 | N12: Bills | O12: =sum(G2:G31) -> 1571.13
A13: 12 | B13: 45759 | C13: =154.5 -> 154.5 | D13: =331 -> 331 | E13: 0 | F13: 0 | G13: 0 | H13: =5666.5 -> 5666.5 | I13: 0 | J13: 0 | K13: 0 | L13: 0 | M13: =SUMIF(C13:L13,"<>") -> 6152 | N13: Total | O13: =+SUM(C2:L31) -> 48412.9
A14: 13 | B14: 45760 | C14: =1557.1+299.97 -> 1857.07 | D14: =5000+234 -> 5234 | E14: 0 | F14: 0 | G14: 0 | H14: =969.34 -> 969.34 | I14: 0 | J14: 0 | K14: 0 | L14: 0 | M14: =SUMIF(C14:L14,"<>") -> 8060.41
A15: 14 | B15: 45761 | C15: =199.39 -> 199.39 | D15: 0 | E15: 0 | F15: 0 | G15: 0 | H15: 0 | I15: 0 | J15: 0 | K15: 0 | L15: 0 | M15: =SUMIF(C15:L15,"<>") -> 199.39
A16: 15 | B16: 45762 | C16: 0 | D16: 0 | E16: 0 | F16: 0 | G16: 0 | H16: 0 | I16: 0 | J16: 0 | K16: 0 | L16: 0 | M16: =SUMIF(C16:L16,"<>") -> 0
A17: 16 | B17: 45763 | C17: =303.22+11 -> 314.22 | D17: 0 | E17: 0 | F17: 0 | G17: 0 | H17: =366 -> 366 | I17: 0 | J17: 0 | K17: 0 | L17: 0 | M17: =SUMIF(C17:L17,"<>") -> 680.22
A18: 17 | B18: 45764 | C18: 0 | D18: 0 | E18: 0 | F18: =15000 -> 15000 | G18: 0 | H18: =177.5 -> 177.5 | I18: 0 | J18: 0 | K18: 0 | L18: 0 | M18: =SUMIF(C18:L18,"<>") -> 15177.5
A19: 18 | B19: 45765 | C19: 0 | D19: 0 | E19: 0 | F19: 0 | G19: 0 | H19: 0 | I19: 0 | J19: 0 | K19: 0 | L19: 0 | M19: =SUMIF(C19:L19,"<>") -> 0
A20: 19 | B20: 45766 | C20: =424.5 -> 424.5 | D20: =465 -> 465 | E20: 0 | F20: 0 | G20: 0 | H20: =306+1335.82 -> 1641.82 | I20: 0 | J20: 0 | K20: 0 | L20: 0 | M20: =SUMIF(C20:L20,"<>") -> 2531.32
A21: 20 | B21: 45767 | C21: =436.33+251.36+362.9 -> 1050.59 | D21: 0 | E21: =780*2 -> 1560 | F21: 0 | G21: =173.88 -> 173.88 | H21: 0 | I21: 0 | J21: 0 | K21: 0 | L21: =333.06 -> 333.06 | M21: =SUMIF(D21:L21,"<>") -> 2066.94
A22: 21 | B22: 45768 | C22: 0 | D22: 0 | E22: 0 | F22: 0 | G22: 0 | H22: =590.45 -> 590.45 | I22: 0 | J22: 0 | K22: 0 | L22: 0 | M22: =SUMIF(C22:L22,"<>") -> 590.45
A23: 22 | B23: 45769 | C23: 0 | D23: 0 | E23: 0 | F23: 0 | G23: 0 | H23: 0 | I23: 0 | J23: 0 | K23: 0 | L23: 0 | M23: =SUMIF(C23:L23,"<>") -> 0
A24: 23 | B24: 45770 | C24: 0 | D24: 0 | E24: 0 | F24: 0 | G24: 0 | H24: 0 | I24: 0 | J24: 0 | K24: 0 | L24: 0 | M24: =SUMIF(C24:L24,"<>") -> 0
A25: 24 | B25: 45771 | C25: 0 | D25: 0 | E25: 0 | F25: 0 | G25: 0 | H25: 0 | I25: 0 | J25: 0 | K25: 0 | L25: 0 | M25: =SUMIF(C25:L25,"<>") -> 0
A26: 25 | B26: 45772 | C26: 0 | D26: 0 | E26: 0 | F26: 0 | G26: 0 | H26: 0 | I26: 0 | J26: 0 | K26: 0 | L26: 0 | M26: =SUMIF(C26:L26,"<>") -> 0
A27: 26 | B27: 45773 | C27: =240+476.99+34 -> 750.99 | D27: 0 | E27: 0 | F27: 0 | G27: 0 | H27: 0 | I27: 0 | J27: 0 | K27: 0 | L27: 0 | M27: =SUMIF(C27:L27,"<>") -> 750.99
A28: 27 | B28: 45774 | C28: 0 | D28: 0 | E28: 0 | F28: 0 | G28: 0 | H28: 0 | I28: 0 | J28: 0 | K28: 0 | L28: 0 | M28: =SUMIF(C28:L28,"<>") -> 0
A29: 28 | B29: 45775 | C29: =262.41 -> 262.41 | D29: 0 | E29: 0 | F29: 0 | G29: 0 | H29: 0 | I29: 0 | J29: 0 | K29: 0 | L29: 0 | M29: =SUMIF(C29:L29,"<>") -> 262.41
A30: 29 | B30: 45776 | C30: 0 | D30: =235+1020 -> 1255 | E30: 0 | F30: 0 | G30: 0 | H30: 0 | I30: 0 | J30: 0 | K30: 0 | L30: 0 | M30: =SUMIF(C30:L30,"<>") -> 1255
A31: 30 | B31: 45777 | C31: 0 | D31: 0 | E31: 0 | F31: 0 | G31: 0 | H31: 0 | I31: 0 | J31: 0 | K31: 0 | L31: 0 | M31: =SUMIF(C31:L31,"<>") -> 0

Sheet MAYIS-2025
B1: Date | C1: Market | D1: Food | E1: Transport | F1: Rent | G1: Bills | H1: Taksit | I1: Abonelik | J1: Fun | K1: Edu | L1: Other | M1: Daily Total
A2: 1 | B2: 45778 | C2: =53.25+453.46 -> 506.71 | D2: =340 -> 340 | E2: 0 | F2: 0 | G2: 0 | H2: 0 | I2: 0 | J2: 0 | K2: 0 | L2: 0 | M2: =SUMIF(C2:L2,"<>") -> 846.71 | N2: Daily Avg. Food | O2: =+SUM(C2:C32,D2:D32)/ COUNTIFS(C2:C32, "<>", D2:D32, "<>") -> 181.80161
A3: 2 | B3: 45779 | C3: 0 | D3: 0 | E3: =548+200 -> 748 | F3: 0 | G3: =760.75 -> 760.75 | H3: =470+406.31 -> 876.31 | I3: =25.82 -> 25.82 | J3: 0 | K3: 0 | L3: =406.31 -> 406.31 | M3: =SUMIF(C3:K3,"<>") -> 2410.88 | N3: Daily Avg | O3: =+O13 / COUNTIF(C2:C32, "<>") -> 1193.4794
A4: 3 | B4: 45780 | C4: =100.3 -> 100.3 | D4: =309.84 -> 309.84 | E4: =798 -> 798 | F4: 0 | G4: =671.5 -> 671.5 | H4: 0 | I4: =19.86 -> 19.86 | J4: =1199+110+1269 -> 2578 | K4: 0 | L4: 0 | M4: =SUMIF(C4:L4,"<>") -> 4477.5 | N4: Market Total | O4: =+SUM(C2:C32) -> 4986.01
A5: 4 | B5: 45781 | C5: 0 | D5: 0 | E5: =31.62 -> 31.62 | F5: 0 | G5: 0 | H5: 0 | I5: 0 | J5: 0 | K5: 0 | L5: 0 | M5: =SUMIF(C5:L5,"<>") -> 31.62 | N5: Food Total | O5: =+SUM(D2:D32) -> 649.84
A6: 5 | B6: 45782 | C6: 0 | D6: 0 | E6: 0 | F6: 0 | G6: 0 | H6: 0 | I6: =39 -> 39 | J6: 0 | K6: 0 | L6: =310+1110-310+415 -> 1525 | M6: =SUMIF(C6:L6,"<>") -> 1564 | N6: Fun Total | O6: =SUM(J2:J32) -> 2578
A7: 6 | B7: 45783 | C7: 0 | D7: 0 | E7: 0 | F7: 0 | G7: 0 | H7: 0 | I7: 0 | J7: 0 | K7: 0 | L7: 0 | M7: =SUMIF(C7:K7,"<>") -> 0 | N7: Edu Total | O7: =SUM(K2:K32) -> 0
A8: 7 | B8: 45784 | C8: 0 | D8: 0 | E8: 0 | F8: 0 | G8: 0 | H8: 0 | I8: 0 | J8: 0 | K8: 0 | L8: 0 | M8: =SUMIF(C8:K8,"<>") -> 0 | N8: Trans. Total | O8: =+SUM(E2:E32) -> 1577.62
A9: 8 | B9: 45785 | C9: =85 -> 85 | D9: 0 | E9: 0 | F9: 0 | G9: 0 | H9: 0 | I9: 0 | J9: 0 | K9: 0 | L9: 0 | M9: =SUMIF(C9:L9,"<>") -> 85 | N9: Taksit Total | O9: =Sum(H2:H32) -> 8184.15
A10: 9 | B10: 45786 | C10: 0 | D10: 0 | E10: 0 | F10: 0 | G10: 0 | H10: 0 | I10: 0 | J10: 0 | K10: 0 | L10: 0 | M10: =SUMIF(C10:L10,"<>") -> 0 | N10: Abonelik Top. | O10: =SUM(I2:I32) -> 84.68
A11: 10 | B11: 45787 | C11: =8.56 -> 8.56 | D11: 0 | E11: 0 | F11: 0 | G11: 0 | H11: 0 | I11: 0 | J11: 0 | K11: 0 | L11: 0 | M11: =SUMIF(C11:L11,"<>") -> 8.56 | N11: Other Total | O11: =+SUM(L2:L32) -> 2505.31
A12: 11 | B12: 45788 | C12: =4.05+15.41+8.56*2+14.63 -> 51.21 | D12: 0 | E12: 0 | F12: 0 | G12: 0 | H12: 0 | I12: 0 | J12: 0 | K12: 0 | L12: 0 | M12: =SUMIF(C12:L12,"<>") -> 51.21 | N12: Bills | O12: =sum(G2:G32) -> 1432.25
A13: 12 | B13: 45789 | C13: =8.56*3+14.63+7.6+18.74+8.56*2+7.6+8.56+12.9 -> 112.83 | D13: 0 | E13: 0 | F13: 0 | G13: 0 | H13: =5666.5 -> 5666.5 | I13: 0 | J13: 0 | K13: 0 | L13: 0 | M13: =SUMIF(C13:L13,"<>") -> 5779.33 | N13: Total | O13: =+SUM(C2:L32) -> 36997.86
A14: 13 | B14: 45790 | C14: =8.56*2+4.05+12+126.94+18.74 -> 178.85 | D14: 0 | E14: 0 | F14: 0 | G14: 0 | H14: =969.34 -> 969.34 | I14: 0 | J14: 0 | K14: 0 | L14: 0 | M14: =SUMIF(C14:L14,"<>") -> 1148.19
A15: 14 | B15: 45791 | C15: =8.56+20.25+14.63+4.05+24+18.74+20.25+8.56+12.9+25.05 -> 156.99 | D15: 0 | E15: 0 | F15: 0 | G15: 0 | H15: 0 | I15: 0 | J15: 0 | K15: 0 | L15: 0 | M15: =SUMIF(C15:L15,"<>") -> 156.99
A16: 15 | B16: 45792 | C16: =85.9+12+7.6+8.56*3+7.6+12.9+24+7.6 -> 183.28 | D16: 0 | E16: 0 | F16: =15000 -> 15000 | G16: 0 | H16: 0 | I16: 0 | J16: 0 | K16: 0 | L16: 0 | M16: =SUMIF(C16:L16,"<>") -> 15183.28
A17: 16 | B17: 45793 | C17: =30.6+8.56*2+20.25+8.56+12+7.6+12+17.1+113.72+105 -> 343.95 | D17: 0 | E17: 0 | F17: 0 | G17: 0 | H17: =366 -> 366 | I17: 0 | J17: 0 | K17: 0 | L17: 0 | M17: =SUMIF(C17:L17,"<>") -> 709.95
A18: 17 | B18: 45794 | C18: =58.95+106.2+172.75+35+8.23+65.5+52+17.1 -> 515.73 | D18: 0 | E18: 0 | F18: 0 | G18: 0 | H18: 0 | I18: 0 | J18: 0 | K18: 0 | L18: 0 | M18: =SUMIF(C18:L18,"<>") -> 515.73
A19: 18 | B19: 45795 | C19: =52+63.85+12*4 -> 163.85 | D19: 0 | E19: 0 | F19: 0 | G19: 0 | H19: 0 | I19: 0 | J19: 0 | K19: 0 | L19: 0 | M19: =SUMIF(C19:L19,"<>") -> 163.85
A20: 19 | B20: 45796 | C20: =98.25+8.23*2+244.43+12*2+17.1*2+12+7.6+8.23+12 -> 457.17 | D20: 0 | E20: 0 | F20: 0 | G20: 0 | H20: =306 -> 306 | I20: 0 | J20: 0 | K20: 0 | L20: 0 | M20: =SUMIF(C20:L20,"<>") -> 763.17
A21: 20 | B21: 45797 | C21: =68.65+8.23+12+8.23+75 -> 172.11 | D21: 0 | E21: 0 | F21: 0 | G21: 0 | H21: 0 | I21: 0 | J21: 0 | K21: 0 | L21: 0 | M21: =SUMIF(D21:L21,"<>") -> 0
A22: 21 | B22: 45798 | C22: =12+115+75+12+10.5+8.23*3+7.6+5 -> 261.79 | D22: 0 | E22: 0 | F22: 0 | G22: 0 | H22: 0 | I22: 0 | J22: 0 | K22: 0 | L22: 0 | M22: =SUMIF(C22:L22,"<>") -> 261.79
A23: 22 | B23: 45799 | C23: =82.3+30.6+20.25+12+8.23+8.23+7.6 -> 169.21 | D23: 0 | E23: 0 | F23: 0 | G23: 0 | H23: 0 | I23: 0 | J23: 0 | K23: 0 | L23: 0 | M23: =SUMIF(C23:L23,"<>") -> 169.21
A24: 23 | B24: 45800 | C24: =7*8.23 -> 57.61 | D24: 0 | E24: 0 | F24: 0 | G24: 0 | H24: 0 | I24: 0 | J24: 0 | K24: 0 | L24: 0 | M24: =SUMIF(C24:L24,"<>") -> 57.61
A25: 24 | B25: 45801 | C25: =219.5+12*3+8.23*4 -> 288.42 | D25: 0 | E25: 0 | F25: 0 | G25: 0 | H25: 0 | I25: 0 | J25: 0 | K25: 0 | L25: 0 | M25: =SUMIF(C25:L25,"<>") -> 288.42
A26: 25 | B26: 45802 | C26: =21.35+15.5+14.63+12+7.26*3 -> 85.26 | D26: 0 | E26: 0 | F26: 0 | G26: 0 | H26: 0 | I26: 0 | J26: 0 | K26: 0 | L26: 0 | M26: =SUMIF(C26:L26,"<>") -> 85.26
A27: 26 | B27: 45803 | C27: =20.25+7.26*2 -> 34.77 | D27: 0 | E27: 0 | F27: 0 | G27: 0 | H27: 0 | I27: 0 | J27: 0 | K27: 0 | L27: =574 -> 574 | M27: =SUMIF(C27:L27,"<>") -> 608.77
A28: 27 | B28: 45804 | C28: =70+7.6*2+7.26*6 -> 128.76 | D28: 0 | E28: 0 | F28: 0 | G28: 0 | H28: 0 | I28: 0 | J28: 0 | K28: 0 | L28: 0 | M28: =SUMIF(C28:L28,"<>") -> 128.76
A29: 28 | B29: 45805 | C29: =96+44+127.6+7.26 -> 274.86 | D29: 0 | E29: 0 | F29: 0 | G29: 0 | H29: 0 | I29: 0 | J29: 0 | K29: 0 | L29: 0 | M29: =SUMIF(C29:L29,"<>") -> 274.86
A30: 29 | B30: 45806 | C30: =86.32+69.95*2+30.6*2+7.6*2+7.26*2 -> 317.14 | D30: 0 | E30: 0 | F30: 0 | G30: 0 | H30: 0 | I30: 0 | J30: 0 | K30: 0 | L30: 0 | M30: =SUMIF(C30:L30,"<>") -> 317.14
A31: 30 | B31: 45807 | C31: =103+60+48.62+14.63+12+7.6*2+7.26*2 -> 267.97 | D31: 0 | E31: 0 | F31: 0 | G31: 0 | H31: 0 | I31: 0 | J31: 0 | K31: 0 | L31: 0 | M31: =SUMIF(C31:L31,"<>") -> 267.97
A32: 31 | B32: 45808 | C32: =25.05+14.63+12+12 -> 63.68 | D32: 0 | E32: 0 | F32: 0 | G32: 0 | H32: 0 | I32: 0 | J32: 0 | K32: 0 | L32: 0 | M32: =SUMIF(C32:L32,"<>") -> 63.68

Sheet HAZİRAN-2025
B1: Date | C1: Market | D1: Food | E1: Transport | F1: Rent | G1: Bills | H1: Taksit | I1: Abonelik | J1: Fun | K1: Edu | L1: Other | M1: Daily Total
A2: 1 | B2: 45809 | C2: =63+39.16+12+7.6*2+7.26*3 -> 151.14 | D2: 0 | E2: 0 | F2: 0 | G2: 0 | H2: 0 | I2: 0 | J2: 0 | K2: 0 | L2: =82 -> 82 | M2: =SUMIF(C2:L2,"<>") -> 233.14 | N2: Daily Avg. Food | O2: =+SUM(C2:C31,D2:D31)/ COUNTIFS(C2:C31, "<>", D2:D31, "<>") -> 731.79267
A3: 2 | B3: 45810 | C3: =71.23+30.6+20.25+12+12+7.88+7.26 -> 161.22 | D3: 0 | E3: 0 | F3: 0 | G3: 0 | H3: =406.31 -> 406.31 | I3: =24.99 -> 24.99 | J3: 0 | K3: 0 | L3: 0 | M3: =SUMIF(C3:K3,"<>") -> 592.52 | N3: Daily Avg | O3: =+O13 / COUNTIF(C2:C31, "<>") -> 2991.0787
A4: 3 | B4: 45811 | C4: =103.93+12+7.26+12+7.26*2+12+7.26+12+7.6+24+46.81 -> 259.38 | D4: 0 | E4: 0 | F4: 0 | G4: 0 | H4: 0 | I4: =18.99 -> 18.99 | J4: 0 | K4: 0 | L4: 0 | M4: =SUMIF(C4:L4,"<>") -> 278.37 | N4: Market Total | O4: =+SUM(C2:C31) -> 2016.34
A5: 4 | B5: 45812 | C5: =80+7.6+12+7.6 -> 107.2 | D5: =190+1160 -> 1350 | E5: 0 | F5: 0 | G5: 0 | H5: 0 | I5: 0 | J5: 0 | K5: 0 | L5: =600 -> 600 | M5: =SUMIF(C5:L5,"<>") -> 2057.2 | N5: Food Total | O5: =+SUM(D2:D31) -> 19937.44
A6: 5 | B6: 45813 | C6: =85 -> 85 | D6: 0 | E6: 0 | F6: 0 | G6: 0 | H6: 0 | I6: =49.9 -> 49.9 | J6: 0 | K6: 0 | L6: 0 | M6: =SUMIF(C6:L6,"<>") -> 134.9 | N6: Fun Total | O6: =SUM(J2:J31) -> 0
A7: 6 | B7: 45814 | C7: =75+90 -> 165 | D7: 0 | E7: 0 | F7: 0 | G7: =92.43+175+504.9+210+671.5 -> 1653.83 | H7: 0 | I7: 0 | J7: 0 | K7: 0 | L7: 0 | M7: =SUMIF(C7:K7,"<>") -> 1818.83 | N7: Edu Total | O7: =SUM(K2:K31) -> 0
A8: 7 | B8: 45815 | C8: 0 | D8: 0 | E8: 0 | F8: 0 | G8: 0 | H8: 0 | I8: 0 | J8: 0 | K8: 0 | L8: 0 | M8: =SUMIF(C8:K8,"<>") -> 0 | N8: Trans. Total | O8: =+SUM(E2:E31) -> 4761.25
A9: 8 | B9: 45816 | C9: =37 -> 37 | D9: =234 -> 234 | E9: 0 | F9: 0 | G9: 0 | H9: 0 | I9: 0 | J9: 0 | K9: 0 | L9: 0 | M9: =SUMIF(C9:L9,"<>") -> 271 | N9: Taksit Total | O9: =Sum(H2:H31) -> 15647.5
A10: 9 | B10: 45817 | C10: 0 | D10: 0 | E10: =780+700 -> 1480 | F10: 0 | G10: 0 | H10: 0 | I10: 0 | J10: 0 | K10: 0 | L10: 0 | M10: =SUMIF(C10:L10,"<>") -> 1480 | N10: Abonelik Top. | O10: =SUM(I2:I31) -> 93.88
A11: 10 | B11: 45818 | C11: =349.25 -> 349.25 | D11: 0 | E11: 0 | F11: 0 | G11: =854.48 -> 854.48 | H11: =470+536 -> 1006 | I11: 0 | J11: 0 | K11: 0 | L11: 0 | M11: =SUMIF(C11:L11,"<>") -> 2209.73 | N11: Other Total | O11: =+SUM(L2:L31) -> 29767.64
A12: 11 | B12: 45819 | C12: 0 | D12: =460 -> 460 | E12: 0 | F12: 0 | G12: 0 | H12: 0 | I12: 0 | J12: 0 | K12: 0 | L12: =30 -> 30 | M12: =SUMIF(C12:L12,"<>") -> 490 | N12: Bills | O12: =sum(G2:G31) -> 2508.31
A13: 12 | B13: 45820 | C13: =85 -> 85 | D13: 0 | E13: 0 | F13: 0 | G13: 0 | H13: =5666.5 -> 5666.5 | I13: 0 | J13: 0 | K13: 0 | L13: 0 | M13: =SUMIF(C13:L13,"<>") -> 5751.5 | N13: Total | O13: =+SUM(C2:L31) -> 89732.36
A14: 13 | B14: 45821 | C14: =69 -> 69 | D14: =280.5 -> 280.5 | E14: 0 | F14: 0 | G14: 0 | H14: =969.34 -> 969.34 | I14: 0 | J14: 0 | K14: 0 | L14: =170 -> 170 | M14: =SUMIF(C14:L14,"<>") -> 1488.84
A15: 14 | B15: 45822 | C15: 0 | D15: 0 | E15: 0 | F15: 0 | G15: 0 | H15: 0 | I15: 0 | J15: 0 | K15: 0 | L15: 0 | M15: =SUMIF(C15:L15,"<>") -> 0
A16: 15 | B16: 45823 | C16: =35+24.95 -> 59.95 | D16: =595 -> 595 | E16: 0 | F16: 0 | G16: 0 | H16: 0 | I16: 0 | J16: 0 | K16: 0 | L16: 0 | M16: =SUMIF(C16:L16,"<>") -> 654.95
A17: 16 | B17: 45824 | C17: =108.75 -> 108.75 | D17: =590 -> 590 | E17: 0 | F17: 0 | G17: 0 | H17: 0 | I17: 0 | J17: 0 | K17: 0 | L17: =256.79 -> 256.79 | M17: =SUMIF(C17:L17,"<>") -> 955.54
A18: 17 | B18: 45825 | C18: =20 -> 20 | D18: 0 | E18: 0 | F18: =15000 -> 15000 | G18: 0 | H18: 0 | I18: 0 | J18: 0 | K18: 0 | L18: 0 | M18: =SUMIF(C18:L18,"<>") -> 15020
A19: 18 | B19: 45826 | C19: =113 -> 113 | D19: =740 -> 740 | E19: 0 | F19: 0 | G19: 0 | H19: =949.5 -> 949.5 | I19: 0 | J19: 0 | K19: 0 | L19: 0 | M19: =SUMIF(C19:L19,"<>") -> 1802.5
A20: 19 | B20: 45827 | C20: =25+100.45+25 -> 150.45 | D20: 0 | E20: 0 | F20: 0 | G20: 0 | H20: 0 | I20: 0 | J20: 0 | K20: 0 | L20: 0 | M20: =SUMIF(C20:L20,"<>") -> 150.45
A21: 20 | B21: 45828 | C21: 0 | D21: 0 | E21: =555 -> 555 | F21: 0 | G21: 0 | H21: 0 | I21: 0 | J21: 0 | K21: 0 | L21: =710 -> 710 | M21: =SUMIF(D21:L21,"<>") -> 1265
A22: 21 | B22: 45829 | C22: =25+70 -> 95 | D22: =610 -> 610 | E22: 0 | F22: 0 | G22: 0 | H22: =6649.85 -> 6649.85 | I22: 0 | J22: 0 | K22: 0 | L22: =120 -> 120 | M22: =SUMIF(C22:L22,"<>") -> 7474.85
A23: 22 | B23: 45830 | C23: 0 | D23: =180 -> 180 | E23: 0 | F23: 0 | G23: 0 | H23: 0 | I23: 0 | J23: 0 | K23: 0 | L23: =664.93 -> 664.93 | M23: =SUMIF(C23:L23,"<>") -> 844.93
A24: 23 | B24: 45831 | C24: 0 | D24: =469.61+1252.93+732.75+567.28+261.32+296.1 -> 3579.99 | E24: =901.41+1075 -> 1976.41 | F24: 0 | G24: 0 | H24: 0 | I24: 0 | J24: 0 | K24: 0 | L24: =18851.53 -> 18851.53 | M24: =SUMIF(C24:L24,"<>") -> 24407.93
A25: 24 | B25: 45832 | C25: 0 | D25: =382.51+1308.57 -> 1691.08 | E25: 0 | F25: 0 | G25: 0 | H25: 0 | I25: 0 | J25: 0 | K25: 0 | L25: =4413.78 -> 4413.78 | M25: =SUMIF(C25:L25,"<>") -> 6104.86
A26: 25 | B26: 45833 | C26: 0 | D26: 0 | E26: 0 | F26: 0 | G26: 0 | H26: 0 | I26: 0 | J26: 0 | K26: 0 | L26: 0 | M26: =SUMIF(C26:L26,"<>") -> 0
A27: 26 | B27: 45834 | C27: 0 | D27: =863.85+287.92+86.37+64.58+719.81 -> 2022.53 | E27: 0 | F27: 0 | G27: 0 | H27: 0 | I27: 0 | J27: 0 | K27: 0 | L27: =1886.71 -> 1886.71 | M27: =SUMIF(C27:L27,"<>") -> 3909.24
A28: 27 | B28: 45835 | C28: 0 | D28: =744.5+478.41+531.47+68.69+429.87+719.88 -> 2972.82 | E28: 0 | F28: 0 | G28: 0 | H28: 0 | I28: 0 | J28: 0 | K28: 0 | L28: =483.34*3+193.34 -> 1643.36 | M28: =SUMIF(C28:L28,"<>") -> 4616.18
A29: 28 | B29: 45836 | C29: 0 | D29: =183.96+1112.31+33.73+783.23+33.73 -> 2146.96 | E29: =749.84 -> 749.84 | F29: 0 | G29: 0 | H29: 0 | I29: 0 | J29: 0 | K29: 0 | L29: =338.54 -> 338.54 | M29: =SUMIF(C29:L29,"<>") -> 3235.34
A30: 29 | B30: 45837 | C30: 0 | D30: =183.96+498.79+650.67+33.75+106.59+33.75*2+865.9 -> 2407.16 | E30: 0 | F30: 0 | G30: 0 | H30: 0 | I30: 0 | J30: 0 | K30: 0 | L30: 0 | M30: =SUMIF(C30:L30,"<>") -> 2407.16
A31: 30 | B31: 45838 | C31: 0 | D31: =77.4 -> 77.4 | E31: 0 | F31: 0 | G31: 0 | H31: 0 | I31: 0 | J31: 0 | K31: 0 | L31: 0 | M31: =SUMIF(C31:L31,"<>") -> 77.4

Sheet TEMMUZ-2025
A1: Shopping | B1: 43060
A2: Taksit | B2: 17604.62 | N2: Daily Avg. Food
A3: Home | B3: 15483.65 | N3: Daily Avg
A4: Market | B4: 11123.51 | N4: Market Total
A5: Health | B5: 9894 | N5: Food Total
A6: Bills | B6: 2568.04 | N6: Fun Total
A7: Entertainment | B7: 1584.5 | N7: Edu Total
A8: Food | B8: 1468.25 | N8: Trans. Total
A9: Transportation | B9: 1445.99 | N9: Taksit Total
A10: Personal Care | B10: 627.48 | N10: Abonelik Top.
A11: Subscription | B11: 93.88 | N11: Other Total
A12: Total | B12: =SUM(B1:B11) -> 104953.92 | N12: Bills
N13: Total
O32: 4

Sheet ARALIK-2023
B1: Date | C1: Food | D1: Transport | E1: Rent | F1: Bills | G1: Taksit | H1: Other | I1: Daily Total | J1: Daily Avg. Food | K1: Daily Avg | L1: Food Total | M1: Trans. Total | N1: Taksit Total | O1: Other Total | P1: Total
A2: 1 | B2: 45261 | C2: =37+44.5+56.4+117.4 -> 255.3 | D2: 0 | E2: 0 | F2: 0 | G2: 0 | H2: 0 | I2: =SUMIF(C2:H2,"<>") -> 255.3 | J2: =+SUM(C2:C32)/COUNTIF(C2:C32,"<>") -> 165.80258 | K2: =+P2 / COUNTIF(C2:C32, "<>") -> 375.38452 | L2: =+SUM(C2:C31) -> 4506.6 | M2: =+SUM(D2:D31) -> 149.95 | N2: =Sum(G2:G32) -> 6148.18 | O2: =+SUM(H2:H31) -> 309.69 | P2: =+SUM(C2:H31) -> 11636.92
A3: 2 | B3: 45262 | C3: =235+29.5+150 -> 414.5 | D3: 0 | E3: 0 | F3: =299.9 -> 299.9 | G3: 0 | H3: =13.47 -> 13.47 | I3: =SUMIF(C3:H3,"<>") -> 727.87
A4: 3 | B4: 45263 | C4: 0 | D4: 0 | E4: 0 | F4: 0 | G4: =1470.16+297.91 -> 1768.07 | H4: 0 | I4: =SUMIF(C4:H4,"<>") -> 1768.07
A5: 4 | B5: 45264 | C5: =58.5 -> 58.5 | D5: 0 | E5: 0 | F5: 0 | G5: =72.5+76.5 -> 149 | H5: 0 | I5: =SUMIF(C5:H5,"<>") -> 207.5
A6: 5 | B6: 45265 | C6: =7+24.5 -> 31.5 | D6: 0 | E6: 0 | F6: 0 | G6: 0 | H6: =39 -> 39 | I6: =SUMIF(C6:H6,"<>") -> 70.5
A7: 6 | B7: 45266 | C7: 0 | D7: 0 | E7: 0 | F7: 0 | G7: 0 | H7: 0 | I7: =SUMIF(C7:H7,"<>") -> 0
A8: 7 | B8: 45267 | C8: 0 | D8: 0 | E8: 0 | F8: =222.6 -> 222.6 | G8: =174.5+459.47 -> 633.97 | H8: 0 | I8: =SUMIF(C8:H8,"<>") -> 856.57
A9: 8 | B9: 45268 | C9: =123.4 -> 123.4 | D9: 0 | E9: 0 | F9: 0 | G9: 0 | H9: 0 | I9: =SUMIF(C9:H9,"<>") -> 123.4
A10: 9 | B10: 45269 | C10: =50+47.51 -> 97.51 | D10: 0 | E10: 0 | F10: 0 | G10: 0 | H10: =12.5 -> 12.5 | I10: =SUMIF(C10:H10,"<>") -> 110.01
A11: 10 | B11: 45270 | C11: =110.63+74.45 -> 185.08 | D11: 0 | E11: 0 | F11: 0 | G11: 0 | H11: 0 | I11: =SUMIF(C11:H11,"<>") -> 185.08 | K11: BORÇLAR
A12: 11 | B12: 45271 | C12: =48+48.45 -> 96.45 | D12: 0 | E12: 0 | F12: 0 | G12: 0 | H12: 0 | I12: =SUMIF(C12:H12,"<>") -> 96.45 | K12: Bu ay | L12: Kira | M12: Diyetisyen | N12: Yoga
A13: 12 | B13: 45272 | C13: =95.45+80+76.7+41.19 -> 293.34 | D13: 0 | E13: 0 | F13: 0 | G13: =230.01 -> 230.01 | H13: =125.36+79.5 -> 204.86 | I13: =SUMIF(C13:H13,"<>") -> 728.21 | K13: =P2 -> 11636.92 | L13: 0 | M13: 0 | N13: 0
A14: 13 | B14: 45273 | C14: =81.55+194.25 -> 275.8 | D14: 0 | E14: 0 | F14: 0 | G14: 0 | H14: 0 | I14: =SUMIF(C14:H14,"<>") -> 275.8 | K14: TOPLAM | M14: =Sum(K13:O13) -> 11636.92
A15: 14 | B15: 45274 | C15: =66.4 -> 66.4 | D15: 0 | E15: 0 | F15: 0 | G15: 0 | H15: 0 | I15: =SUMIF(C15:H15,"<>") -> 66.4
A16: 15 | B16: 45275 | C16: =30 -> 30 | D16: 0 | E16: 0 | F16: 0 | G16: 0 | H16: 0 | I16: =SUMIF(C16:H16,"<>") -> 30
A17: 16 | B17: 45276 | C17: =130 -> 130 | D17: 0 | E17: 0 | F17: 0 | G17: =162.5+62.5 -> 225 | H17: =19.9 -> 19.9 | I17: =SUMIF(C17:H17,"<>") -> 374.9
A18: 17 | B18: 45277 | C18: =60.75+27 -> 87.75 | D18: 0 | E18: 0 | F18: 0 | G18: 0 | H18: 0 | I18: =SUMIF(C18:H18,"<>") -> 87.75
A19: 18 | B19: 45278 | C19: 0 | D19: 0 | E19: 0 | F19: 0 | G19: 0 | H19: 0 | I19: =SUMIF(C19:H19,"<>") -> 0
A20: 19 | B20: 45279 | C20: =107.85+8.25+37.47 -> 153.57 | D20: 0 | E20: 0 | F20: 0 | G20: 0 | H20: 0 | I20: =SUMIF(C20:H20,"<>") -> 153.57
A21: 20 | B21: 45280 | C21: =112.75+66.7 -> 179.45 | D21: 0 | E21: 0 | F21: 0 | G21: =155.75 -> 155.75 | H21: 0 | I21: =SUMIF(C21:H21,"<>") -> 335.2
A22: 21 | B22: 45281 | C22: =33+30 -> 63 | D22: 0 | E22: 0 | F22: 0 | G22: 0 | H22: 0 | I22: =SUMIF(C22:H22,"<>") -> 63
A23: 22 | B23: 45282 | C23: 20 | D23: 0 | E23: 0 | F23: 0 | G23: 0 | H23: 0 | I23: =SUMIF(C23:H23,"<>") -> 20
A24: 23 | B24: 45283 | C24: =84+50+165+117.96 -> 416.96 | D24: 0 | E24: 0 | F24: 0 | G24: =490.32 -> 490.32 | H24: 0 | I24: =SUMIF(C24:H24,"<>") -> 907.28
A25: 24 | B25: 45284 | C25: =38.8+235+85 -> 358.8 | D25: 0 | E25: 0 | F25: 0 | G25: 0 | H25: 0 | I25: =SUMIF(C25:H25,"<>") -> 358.8
A26: 25 | B26: 45285 | C26: =51.5 -> 51.5 | D26: 0 | E26: 0 | F26: 0 | G26: 0 | H26: =19.96 -> 19.96 | I26: =SUMIF(C26:H26,"<>") -> 71.46
A27: 26 | B27: 45286 | C27: =61.9+48+43.5+129.74 -> 283.14 | D27: 0 | E27: 0 | F27: 0 | G27: =87.47+94.37+463.7 -> 645.54 | H27: 0 | I27: =SUMIF(C27:H27,"<>") -> 928.68
A28: 27 | B28: 45287 | C28: 0 | D28: 0 | E28: 0 | F28: 0 | G28: 0 | H28: 0 | I28: =SUMIF(C28:H28,"<>") -> 0
A29: 28 | B29: 45288 | C29: =249.04 -> 249.04 | D29: 0 | E29: 0 | F29: 0 | G29: =16.31+10.87+108.74+1714.6 -> 1850.52 | H29: 0 | I29: =SUMIF(C29:H29,"<>") -> 2099.56
A30: 29 | B30: 45289 | C30: =28.75+25.5+32.5 -> 86.75 | D30: 0 | E30: 0 | F30: 0 | G30: 0 | H30: 0 | I30: =SUMIF(C30:H30,"<>") -> 86.75
A31: 30 | B31: 45290 | C31: =200+84+114.86+100 -> 498.86 | D31: =74.95+75 -> 149.95 | E31: 0 | F31: 0 | G31: 0 | H31: 0 | I31: =SUMIF(C31:H31,"<>") -> 648.81
A32: 31 | B32: 45291 | C32: =55.85+171.93+405.5 -> 633.28 | D32: 0 | E32: 0 | F32: 0 | G32: 0 | H32: 0 | I32: =SUMIF(C32:H32,"<>") -> 633.28

Sheet OCAK-2024
B1: Date | C1: Market | D1: Yemek | E1: Transport | F1: Rent | G1: Bills | H1: Taksit | I1: Other | J1: Daily Total | K1: Daily Avg. Food | L1: Daily Avg | M1: Market Total | N1: Yemek Total | O1: Trans. Total | P1: Taksit Total | Q1: Other Total | R1: Total
A2: 1 | B2: 45292 | C2: =122.5 -> 122.5 | D2: 0 | E2: 0 | F2: 0 | G2: 0 | H2: 0 | I2: 0 | J2: =SUMIF(C2:I2,"<>") -> 122.5 | K2: =+SUM(C2:C32,D2:D32)/ COUNTIFS(C2:C32, "<>", D2:D32, "<>") -> 195.05194 | L2: =+R2 / COUNTIF(C2:C32, "<>") -> 431.86806 | M2: =+SUM(C2:C31) -> 5001.94 | N2: =+SUM(D2:D31) -> 902.15 | O2: =+SUM(E2:E31) -> 300.9 | P2: =Sum(H2:H32) -> 6090.36 | Q2: =+SUM(I2:I31) -> 563.26 | R2: =+SUM(C2:I31) -> 13387.91
A3: 2 | B3: 45293 | C3: 0 | D3: =280 -> 280 | E3: 0 | F3: 0 | G3: 0 | H3: 0 | I3: =13.54 -> 13.54 | J3: =SUMIF(C3:I3,"<>") -> 293.54
A4: 3 | B4: 45294 | C4: 0 | D4: 0 | E4: 0 | F4: 0 | G4: 0 | H4: =297.91+1470.16 -> 1768.07 | I4: 0 | J4: =SUMIF(C4:I4,"<>") -> 1768.07
A5: 4 | B5: 45295 | C5: 0 | D5: 0 | E5: 0 | F5: 0 | G5: 0 | H5: =76.5+72.5 -> 149 | I5: 0 | J5: =SUMIF(C5:I5,"<>") -> 149
A6: 5 | B6: 45296 | C6: =26.24 -> 26.24 | D6: 0 | E6: 0 | F6: 0 | G6: =299.9+229.4 -> 529.3 | H6: 0 | I6: =39+20 -> 59 | J6: =SUMIF(C6:I6,"<>") -> 614.54
A7: 6 | B7: 45297 | C7: 0 | D7: 0 | E7: 0 | F7: 0 | G7: 0 | H7: 0 | I7: 0 | J7: =SUMIF(C7:I7,"<>") -> 0
A8: 7 | B8: 45298 | C8: =188.55+123.65+27 -> 339.2 | D8: 0 | E8: 0 | F8: 0 | G8: 0 | H8: =459.47 -> 459.47 | I8: 0 | J8: =SUMIF(C8:I8,"<>") -> 798.67
A9: 8 | B9: 45299 | C9: =173.33 -> 173.33 | D9: 0 | E9: 0 | F9: 0 | G9: 0 | H9: 0 | I9: 0 | J9: =SUMIF(C9:I9,"<>") -> 173.33
A10: 9 | B10: 45300 | C10: =81.1+11.65+73.63+195.25 -> 361.63 | D10: 0 | E10: 0 | F10: 0 | G10: 0 | H10: 0 | I10: 0 | J10: =SUMIF(C10:I10,"<>") -> 361.63
A11: 10 | B11: 45301 | C11: =109 -> 109 | D11: 0 | E11: 0 | F11: 0 | G11: 0 | H11: 0 | I11: 0 | J11: =SUMIF(C11:I11,"<>") -> 109 | L11: BORÇLAR
A12: 11 | B12: 45302 | C12: =137.82 -> 137.82 | D12: 0 | E12: 0 | F12: 0 | G12: 0 | H12: 0 | I12: =104.95 -> 104.95 | J12: =SUMIF(C12:I12,"<>") -> 242.77 | L12: Bu ay | M12: Kira | N12: Diyetisyen
A13: 12 | B13: 45303 | C13: =444.2+134.71 -> 578.91 | D13: 0 | E13: 0 | F13: 0 | G13: 0 | H13: =229.98 -> 229.98 | I13: =126.15 -> 126.15 | J13: =SUMIF(C13:I13,"<>") -> 935.04 | L13: =R2 -> 13387.91 | M13: 0 | N13: 0
A14: 13 | B14: 45304 | C14: 0 | D14: 0 | E14: 0 | F14: 0 | G14: 0 | H14: 0 | I14: 0 | J14: =SUMIF(C14:I14,"<>") -> 0 | L14: TOPLAM | M14: =Sum(L13:O13) -> 13387.91
A15: 14 | B15: 45305 | C15: =96.27+80 -> 176.27 | D15: 0 | E15: 0 | F15: 0 | G15: 0 | H15: 0 | I15: 0 | J15: =SUMIF(C15:I15,"<>") -> 176.27
A16: 15 | B16: 45306 | C16: =138.83+44.9+55 -> 238.73 | D16: =99.9 -> 99.9 | E16: 0 | F16: 0 | G16: 0 | H16: 0 | I16: =19.9 -> 19.9 | J16: =SUMIF(C16:I16,"<>") -> 358.53
A17: 16 | B17: 45307 | C17: 0 | D17: 0 | E17: 0 | F17: 0 | G17: 0 | H17: =301.49 -> 301.49 | I17: 0 | J17: =SUMIF(C17:I17,"<>") -> 301.49
A18: 17 | B18: 45308 | C18: 0 | D18: 0 | E18: 0 | F18: 0 | G18: 0 | H18: 0 | I18: 0 | J18: =SUMIF(C18:I18,"<>") -> 0
A19: 18 | B19: 45309 | C19: =24.9+208.94 -> 233.84 | D19: 0 | E19: 0 | F19: 0 | G19: 0 | H19: 0 | I19: =220 -> 220 | J19: =SUMIF(C19:I19,"<>") -> 453.84
A20: 19 | B20: 45310 | C20: =231.35 -> 231.35 | D20: 0 | E20: 0 | F20: 0 | G20: 0 | H20: 0 | I20: 0 | J20: =SUMIF(C20:I20,"<>") -> 231.35
A21: 20 | B21: 45311 | C21: =131.75 -> 131.75 | D21: 0 | E21: 0 | F21: 0 | G21: 0 | H21: 0 | I21: 0 | J21: =SUMIF(C21:I21,"<>") -> 131.75
A22: 21 | B22: 45312 | C22: =175 -> 175 | D22: 0 | E22: 0 | F22: 0 | G22: 0 | H22: =106.25 -> 106.25 | I22: 0 | J22: =SUMIF(C22:I22,"<>") -> 281.25
A23: 22 | B23: 45313 | C23: =83.21+171.99+308.95 -> 564.15 | D23: =185 -> 185 | E23: 0 | F23: 0 | G23: 0 | H23: =67.51 -> 67.51 | I23: =19.72 -> 19.72 | J23: =SUMIF(C23:I23,"<>") -> 836.38
A24: 23 | B24: 45314 | C24: =179.08+39.9+169.75 -> 388.73 | D24: =157.25 -> 157.25 | E24: 0 | F24: 0 | G24: 0 | H24: =600 -> 600 | I24: 0 | J24: =SUMIF(C24:I24,"<>") -> 1145.98
A25: 24 | B25: 45315 | C25: 0 | D25: 0 | E25: 0 | F25: 0 | G25: 0 | H25: 0 | I25: 0 | J25: =SUMIF(C25:I25,"<>") -> 0
A26: 25 | B26: 45316 | C26: 0 | D26: 0 | E26: 0 | F26: 0 | G26: 0 | H26: 0 | I26: 0 | J26: =SUMIF(C26:I26,"<>") -> 0
A27: 26 | B27: 45317 | C27: =337.65 -> 337.65 | D27: 0 | E27: 0 | F27: 0 | G27: 0 | H27: =463.7+94.37 -> 558.07 | I27: 0 | J27: =SUMIF(C27:I27,"<>") -> 895.72
A28: 27 | B28: 45318 | C28: =115+87.2+175.36+39.5 -> 417.06 | D28: 0 | E28: =98.95 -> 98.95 | F28: 0 | G28: 0 | H28: 0 | I28: 0 | J28: =SUMIF(C28:I28,"<>") -> 516.01
A29: 28 | B29: 45319 | C29: 0 | D29: 0 | E29: 0 | F29: 0 | G29: 0 | H29: =1850.52 -> 1850.52 | I29: 0 | J29: =SUMIF(C29:I29,"<>") -> 1850.52
